Workbook

Sheet 📋 INDEX
B2: 🎯 Excel Formulas & Functions — Complete Workbook
B3: 11 Topic Sheets · All Formulas · Example Data · Exercises · Indian Context
B5: Sheet Name | C5: Topic | D5: Key Functions & Content
B6: 01_Tables_CtrlT | C6: 📊 Tables (Ctrl+T) | D6: Smart tables, auto-expand, structured refs, total row
B7: 02_Logical_IF_IFS_AND_OR | C7: 🧠 Logical Functions | D7: IF, IFS, AND, OR, NOT — conditional logic with student exam data
B8: 03_Text_Functions | C8: 📝 Text Functions | D8: LEFT, RIGHT, MID, LEN, TRIM, UPPER, LOWER, CONCAT, TEXTJOIN
B9: 04_Date_Functions | C9: 📅 Date Functions | D9: TODAY, NOW, DATE, EDATE, DATEDIF, NETWORKDAYS — with employee tenure
B10: 05_Math_Stat_Functions | C10: 🔢 Math & Stat | D10: SUM, AVERAGE, COUNT, COUNTA, ROUND, INT, MOD — with product data
B11: 06_Lookup_VLOOKUP_HLOOKUP | C11: 🔍 VLOOKUP & HLOOKUP | D11: Vertical and horizontal lookups, IFERROR, comparison with XLOOKUP
B12: 07_Conditional_Formatting | C12: 🎨 Conditional Formatting | D12: Greater than, top 10%, duplicates, color scales, data bars, icon sets
B13: 08_Charts_Column_Bar_Line_Pie | C13: 📊 Charts | D13: Column, Bar, Line, Pie, Combo — chart selection guide + exercises
B14: 09_Pivot_Tables | C14: 🔄 Pivot Tables | D14: Create, group, filter, drill-down, slicer, PivotChart — order data
B15: 10_XLOOKUP_Advanced | C15: 🚀 XLOOKUP Advanced | D15: Syntax, wildcard, multi-col, 2-way, reverse search, vs VLOOKUP
B16: 11_Advanced_Integration | C16: ⚡ Advanced Integration | D16: XLOOKUP+Pivot, nested formulas, cross-sheet, use cases, dashboard
B18: 💡 Each sheet contains: Sample Data (Indian context) → Formula Examples → Function Reference → Exercises → Tips

Sheet 01_Tables_CtrlT
A1: 📊 INTRODUCTION TO TABLES (Ctrl+T) — Smart, Auto-Expanding Data Ranges
A2: CONCEPT: Format data as an Excel Table to enable auto-filters, structured references, and automatic formula expansion.
A4: SAMPLE DATA — Indian Sales Team Performance (Format this range as a Table → Ctrl+T)
A5: Emp ID | B5: Employee Name | C5: City | D5: Department | E5: Sales (₹) | F5: Target (₹) | G5: % Achieved | H5: Status
A6: E001 | B6: Aarav Shah | C6: Mumbai | D6: Sales | E6: 285000 | F6: 250000 | G6: =E6/F6 | H6: =IF(G6>=1,"✅ Achieved","❌ Missed")
A7: E002 | B7: Diya Sharma | C7: Delhi | D7: Sales | E7: 198000 | F7: 220000 | G7: =E7/F7 | H7: =IF(G7>=1,"✅ Achieved","❌ Missed")
A8: E003 | B8: Vivaan Reddy | C8: Bengaluru | D8: Marketing | E8: 310000 | F8: 300000 | G8: =E8/F8 | H8: =IF(G8>=1,"✅ Achieved","❌ Missed")
A9: E004 | B9: Ananya Nair | C9: Hyderabad | D9: Sales | E9: 175000 | F9: 200000 | G9: =E9/F9 | H9: =IF(G9>=1,"✅ Achieved","❌ Missed")
A10: E005 | B10: Kabir Mehta | C10: Chennai | D10: Marketing | E10: 260000 | F10: 250000 | G10: =E10/F10 | H10: =IF(G10>=1,"✅ Achieved","❌ Missed")
A11: E006 | B11: Ishaan Bose | C11: Kolkata | D11: Sales | E11: 340000 | F11: 300000 | G11: =E11/F11 | H11: =IF(G11>=1,"✅ Achieved","❌ Missed")
A12: E007 | B12: Myra Joshi | C12: Pune | D12: HR | E12: 95000 | F12: 100000 | G12: =E12/F12 | H12: =IF(G12>=1,"✅ Achieved","❌ Missed")
A13: E008 | B13: Aryan Patel | C13: Ahmedabad | D13: Sales | E13: 215000 | F13: 220000 | G13: =E13/F13 | H13: =IF(G13>=1,"✅ Achieved","❌ Missed")
A14: E009 | B14: Kiara Gupta | C14: Jaipur | D14: Marketing | E14: 188000 | F14: 180000 | G14: =E14/F14 | H14: =IF(G14>=1,"✅ Achieved","❌ Missed")
A15: E010 | B15: Reyansh Singh | C15: Lucknow | D15: Sales | E15: 305000 | F15: 280000 | G15: =E15/F15 | H15: =IF(G15>=1,"✅ Achieved","❌ Missed")
A16: E011 | B16: Ira Desai | C16: Surat | D16: HR | E16: 88000 | F16: 100000 | G16: =E16/F16 | H16: =IF(G16>=1,"✅ Achieved","❌ Missed")
A17: E012 | B17: Shaurya Verma | C17: Kanpur | D17: Sales | E17: 240000 | F17: 230000 | G17: =E17/F17 | H17: =IF(G17>=1,"✅ Achieved","❌ Missed")
... A20: E015 | B20: Zara Malhotra | C20: Bhopal | D20: HR | E20: 110000 | F20: 100000 | G20: =E20/F20 | H20: =IF(G20>=1,"✅ Achieved","❌ Missed")
A21: TOTALS | B21: 15 Employees | E21: =SUM(E6:E20) | F21: =SUM(F6:F20) | G21: =E21/F21 | H21: =COUNTIF(H6:H20,"✅ Achieved")&" of 15"
A23: TABLE BENEFITS & KEY FEATURES
A24: Feature | B24: What It Does | C24: Example / Action
A25: Auto-Filter Dropdowns | B25: Dropdown arrows appear on every column header automatically. | C25: =Ctrl+T on any range
A26: Structured References | B26: Use =Table1[Sales] instead of =$E$6:$E$20. Much easier to read. | C26: =SUM(Table1[Sales (₹)])
A27: Auto-Expansion | B27: Add a new row below the table — formulas fill down automatically. | C27: Type in row 21 to test
A28: Total Row | B28: Right-click table → Table → Toggle Total Row for instant aggregates. | C28: SUM, AVG, COUNT, MAX...
A29: Named Table | B29: Every table has a name (Table1). Rename in Table Design → Table Name. | C29: Use name in VLOOKUP etc.
A31: ✏️ EXERCISE — Apply Ctrl+T, Rename, Add Total Row, Sort, Filter
A32: 1. Select the data range (including headers) → Press Ctrl+T → Confirm 'My table has headers' → OK
A33: 2. Go to Table Design tab → Change Table Name from 'Table1' to 'SalesTeam'
A34: 3. Click any cell in the table → Table Design → check 'Total Row' → see aggregates appear
A35: 4. Click the Department filter dropdown → show only 'Sales' department employees
A36: 5. Sort the table by 'Sales (₹)' column — Largest to Smallest
A37: 6. In an empty cell, type: =SUM(SalesTeam[Sales (₹)]) — observe structured reference
A38: 7. Add a new employee row below the last row → observe formula auto-fill in columns G and H
A39: 💡 Ctrl+T is the FIRST thing a data analyst does on any new dataset. Tables are the foundation of all professional Excel work.

Sheet 02_Logical_IF_IFS_AND_OR
A1: 🧠 LOGICAL FUNCTIONS — IF, IFS, AND, OR, NOT
A2: Logical functions evaluate conditions and return different values based on TRUE/FALSE outcomes.
A4: SAMPLE DATA — Student Exam Results (Indian Students)
A5: S.No | B5: Student Name | C5: City | D5: Math | E5: Science | F5: English | G5: Total | H5: Average | I5: Grade | J5: Pass/Fail
A6: 1 | B6: Aarav Shah | C6: Mumbai | D6: 88 | E6: 92 | F6: 78 | G6: =D6+E6+F6 | H6: =ROUND(G6/3,1) | I6: =IFS(H6>=90,"A+",H6>=80,"A",H6>=70,"B+",H6>=60,"B",H6>=50,"C",TRUE,"F") | J6: =IF(AND(D6>=40,E6>=40,F6>=40),"✅ Pass","❌ Fail")
A7: 2 | B7: Diya Sharma | C7: Delhi | D7: 72 | E7: 68 | F7: 80 | G7: =D7+E7+F7 | H7: =ROUND(G7/3,1) | I7: =IFS(H7>=90,"A+",H7>=80,"A",H7>=70,"B+",H7>=60,"B",H7>=50,"C",TRUE,"F") | J7: =IF(AND(D7>=40,E7>=40,F7>=40),"✅ Pass","❌ Fail")
A8: 3 | B8: Vivaan Reddy | C8: Bengaluru | D8: 95 | E8: 88 | F8: 92 | G8: =D8+E8+F8 | H8: =ROUND(G8/3,1) | I8: =IFS(H8>=90,"A+",H8>=80,"A",H8>=70,"B+",H8>=60,"B",H8>=50,"C",TRUE,"F") | J8: =IF(AND(D8>=40,E8>=40,F8>=40),"✅ Pass","❌ Fail")
A9: 4 | B9: Ananya Nair | C9: Hyderabad | D9: 45 | E9: 58 | F9: 62 | G9: =D9+E9+F9 | H9: =ROUND(G9/3,1) | I9: =IFS(H9>=90,"A+",H9>=80,"A",H9>=70,"B+",H9>=60,"B",H9>=50,"C",TRUE,"F") | J9: =IF(AND(D9>=40,E9>=40,F9>=40),"✅ Pass","❌ Fail")
A10: 5 | B10: Kabir Mehta | C10: Chennai | D10: 78 | E10: 75 | F10: 80 | G10: =D10+E10+F10 | H10: =ROUND(G10/3,1) | I10: =IFS(H10>=90,"A+",H10>=80,"A",H10>=70,"B+",H10>=60,"B",H10>=50,"C",TRUE,"F") | J10: =IF(AND(D10>=40,E10>=40,F10>=40),"✅ Pass","❌ Fail")
A11: 6 | B11: Ishaan Bose | C11: Kolkata | D11: 55 | E11: 60 | F11: 50 | G11: =D11+E11+F11 | H11: =ROUND(G11/3,1) | I11: =IFS(H11>=90,"A+",H11>=80,"A",H11>=70,"B+",H11>=60,"B",H11>=50,"C",TRUE,"F") | J11: =IF(AND(D11>=40,E11>=40,F11>=40),"✅ Pass","❌ Fail")
A12: 7 | B12: Myra Joshi | C12: Pune | D12: 91 | E12: 94 | F12: 89 | G12: =D12+E12+F12 | H12: =ROUND(G12/3,1) | I12: =IFS(H12>=90,"A+",H12>=80,"A",H12>=70,"B+",H12>=60,"B",H12>=50,"C",TRUE,"F") | J12: =IF(AND(D12>=40,E12>=40,F12>=40),"✅ Pass","❌ Fail")
A13: 8 | B13: Aryan Patel | C13: Ahmedabad | D13: 38 | E13: 45 | F13: 55 | G13: =D13+E13+F13 | H13: =ROUND(G13/3,1) | I13: =IFS(H13>=90,"A+",H13>=80,"A",H13>=70,"B+",H13>=60,"B",H13>=50,"C",TRUE,"F") | J13: =IF(AND(D13>=40,E13>=40,F13>=40),"✅ Pass","❌ Fail")
A14: 9 | B14: Kiara Gupta | C14: Jaipur | D14: 82 | E14: 79 | F14: 76 | G14: =D14+E14+F14 | H14: =ROUND(G14/3,1) | I14: =IFS(H14>=90,"A+",H14>=80,"A",H14>=70,"B+",H14>=60,"B",H14>=50,"C",TRUE,"F") | J14: =IF(AND(D14>=40,E14>=40,F14>=40),"✅ Pass","❌ Fail")
A15: 10 | B15: Reyansh Singh | C15: Lucknow | D15: 67 | E15: 70 | F15: 63 | G15: =D15+E15+F15 | H15: =ROUND(G15/3,1) | I15: =IFS(H15>=90,"A+",H15>=80,"A",H15>=70,"B+",H15>=60,"B",H15>=50,"C",TRUE,"F") | J15: =IF(AND(D15>=40,E15>=40,F15>=40),"✅ Pass","❌ Fail")
A16: 11 | B16: Ira Desai | C16: Surat | D16: 99 | E16: 97 | F16: 95 | G16: =D16+E16+F16 | H16: =ROUND(G16/3,1) | I16: =IFS(H16>=90,"A+",H16>=80,"A",H16>=70,"B+",H16>=60,"B",H16>=50,"C",TRUE,"F") | J16: =IF(AND(D16>=40,E16>=40,F16>=40),"✅ Pass","❌ Fail")
A17: 12 | B17: Zara Malhotra | C17: Bhopal | D17: 50 | E17: 55 | F17: 48 | G17: =D17+E17+F17 | H17: =ROUND(G17/3,1) | I17: =IFS(H17>=90,"A+",H17>=80,"A",H17>=70,"B+",H17>=60,"B",H17>=50,"C",TRUE,"F") | J17: =IF(AND(D17>=40,E17>=40,F17>=40),"✅ Pass","❌ Fail")
A19: FORMULA REFERENCE — Syntax, Logic & Examples
A20: Function | B20: Syntax | C20: Example Used Above | D20: What It Returns
A21: IF | B21: =IF(condition, value_if_true, value_if_false) | C21: =IF(H6>=90,"A+","Below A+") | D21: Returns 'A+' if average ≥ 90, otherwise 'Below A+'
A22: IFS | B22: =IFS(cond1,val1, cond2,val2, ..., TRUE,default) | C22: =IFS(H6>=90,"A+",H6>=80,"A",...,TRUE,"F") | D22: Tests multiple conditions in order, returns first TRUE match
A23: AND | B23: =AND(condition1, condition2, ...) | C23: =AND(D6>=40, E6>=40, F6>=40) | D23: TRUE only if ALL conditions are true
A24: OR | B24: =OR(condition1, condition2, ...) | C24: =OR(D6>=90, E6>=90, F6>=90) | D24: TRUE if ANY condition is true
A25: NOT | B25: =NOT(condition) | C25: =NOT(J6="✅ Pass") | D25: Reverses TRUE to FALSE and FALSE to TRUE
A27: ADDITIONAL FORMULA EXAMPLES (applied to above data)
A28: What We Want | B28: Formula | C28: Result (live)
A29: Top Scorer | B29: =INDEX(B6:B17,MATCH(MAX(H6:H17),H6:H17,0)) | C29: =INDEX(B6:B17,MATCH(MAX(H6:H17),H6:H17,0))
A30: Pass Count | B30: =COUNTIF(J6:J17,"✅ Pass") | C30: =COUNTIF(J6:J17,"✅ Pass")
A31: A+ Students | B31: =COUNTIF(I6:I17,"A+") | C31: =COUNTIF(I6:I17,"A+")
A32: Avg of Passers | B32: =AVERAGEIF(J6:J17,"✅ Pass",H6:H17) | C32: =AVERAGEIF(J6:J17,"✅ Pass",H6:H17)
A33: Any Below 40 Math | B33: =IF(COUNTIF(D6:D17,"<40")>0,"Yes — has failures","No — all passed") | C33: =IF(COUNTIF(D6:D17,"<40")>0,"Yes — has failures","No — all passed")
A35: ✏️ EXERCISE — Write IF, IFS, AND, OR formulas on this data
A36: Q1: Write an IF formula to flag students who scored > 85 average as 'Merit' else 'Standard' (Column K)
A37: Q2: Use AND to check if a student passed ALL 3 subjects AND has average >= 70 (Column L)
A38: Q3: Use OR to find if any single subject score is >= 95 (Column M)
A39: Q4: Use IFS to assign scholarship: avg>=90→'Full', avg>=80→'Half', avg>=70→'25%', else 'None' (Column N)
A40: Q5: Use NOT to create a 'Needs Improvement' flag — NOT(passed AND grade is A or A+)
A41: Q6: Count how many students are in each grade (A+, A, B+, B, C, F) using COUNTIF
A42: 💡 IFS replaces nested IF for multiple conditions. AND/OR can be nested inside IF for compound conditions.

Sheet 03_Text_Functions
A1: 📝 TEXT FUNCTIONS — LEFT, RIGHT, MID, LEN, TRIM, UPPER, LOWER, CONCAT, TEXTJOIN
A2: Text functions manipulate, extract, combine and clean text strings. Essential for data cleaning in analytics.
A4: SAMPLE DATA — Employee Records with Text Cleaning Needs
A5: Raw Full Name | B5: City | C5: Email (Messy) | D5: Phone | E5: Dept Code
A6: Aarav.Shah | B6: MUMBAI | C6: AARAV.SHAH@GMAIL.COM | D6: 9876543210 | E6: SALES-MH-001
A7: Diya.Sharma | B7: DELHI | C7: diya.sharma@YAHOO.COM | D7: 8765432109 | E7: MKT-DL-002
A8: Vivaan.Reddy | B8: BENGALURU | C8: vivaan.reddy@gmail.com | D8: 7654321098 | E8: SALES-KA-003
A9: Ananya.Nair | B9: HYDERABAD | C9: ANANYA.NAIR@OUTLOOK.COM | D9: 6543210987 | E9: HR-TS-004
A10: Kabir.Mehta | B10: CHENNAI | C10: kabir.mehta@gmail.com | D10: 5432109876 | E10: MKT-TN-005
A11: Ishaan.Bose | B11: KOLKATA | C11: ISHAAN.BOSE@GMAIL.COM | D11: 4321098765 | E11: SALES-WB-006
A12: Myra.Joshi | B12: PUNE | C12: myra.joshi@yahoo.com | D12: 3210987654 | E12: HR-MH-007
A13: Aryan.Patel | B13: AHMEDABAD | C13: aryan.patel@gmail.com | D13: 2109876543 | E13: SALES-GJ-008
A15: FORMULA OUTPUTS — Cleaned & Extracted Data
A16: Formula | B16: Applied To | C16: Result Column | D16: Description
A17: =TRIM(A6) | B17: Raw Full Name | C17: =TRIM(A6) | D17: Removes leading/trailing spaces
A18: =PROPER(TRIM(A6)) | B18: Full Name | C18: =PROPER(TRIM(A6)) | D18: Title case after trimming
A19: =LEFT(TRIM(A6),FIND(".",TRIM(A6))-1) | B19: Full Name | C19: =LEFT(TRIM(A6),FIND(".",TRIM(A6))-1) | D19: Extract First Name
A20: =MID(TRIM(A6),FIND(".",TRIM(A6))+1,LEN(TRIM(A6))) | B20: Full Name | C20: =MID(TRIM(A6),FIND(".",TRIM(A6))+1,LEN(TRIM(A6))) | D20: Extract Last Name
A21: =LEN(TRIM(A6)) | B21: Full Name | C21: =LEN(TRIM(A6)) | D21: Character count of cleaned name
A22: =UPPER(B6) | B22: City | C22: =UPPER(B6) | D22: Uppercase city name
A23: =LOWER(TRIM(C6)) | B23: Email | C23: =LOWER(TRIM(C6)) | D23: Lowercase and trimmed email
A24: =RIGHT(D6,10) | B24: Phone | C24: =RIGHT(D6,10) | D24: Last 10 digits of phone
A25: =LEFT(E6,FIND("-",E6)-1) | B25: Dept Code | C25: =LEFT(E6,FIND("-",E6)-1) | D25: Extract department prefix (SALES, MKT, HR)
A26: =CONCAT(LOWER(LEFT(TRIM(A6),4)),"@company.in") | B26: Name | C26: =CONCAT(LOWER(LEFT(TRIM(A6),4)),"@company.in") | D26: Build company email
A27: =TEXTJOIN(" | ",TRUE,TRIM(A6),B6,LEFT(E6,FIND("-",E6)-1)) | B27: Multiple | C27: =TEXTJOIN(" | ",TRUE,TRIM(A6),B6,LEFT(E6,FIND("-",E6)-1)) | D27: Join Name+City+Dept
A28: =SUBSTITUTE(C6," ","") | B28: Email | C28: =SUBSTITUTE(C6," ","") | D28: Remove all spaces from email
A30: FUNCTION QUICK REFERENCE
A31: Function | B31: Syntax | C31: Example | D31: Result | E31: Purpose
A32: LEFT | B32: =LEFT(text, n) | C32: =LEFT("Aarav.Shah",5) | D32: Aarav | E32: Extract n chars from left
A33: RIGHT | B33: =RIGHT(text, n) | C33: =RIGHT("Aarav.Shah",4) | D33: Shah | E33: Extract n chars from right
A34: MID | B34: =MID(text, start, n) | C34: =MID("Aarav.Shah",7,4) | D34: Shah | E34: Extract from middle
A35: LEN | B35: =LEN(text) | C35: =LEN("Aarav.Shah") | D35: 10 | E35: Count characters
A36: TRIM | B36: =TRIM(text) | C36: =TRIM(" Aarav ") | D36: Aarav | E36: Remove extra spaces
A37: UPPER | B37: =UPPER(text) | C37: =UPPER("aarav") | D37: AARAV | E37: All uppercase
A38: LOWER | B38: =LOWER(text) | C38: =LOWER("AARAV") | D38: aarav | E38: All lowercase
A39: PROPER | B39: =PROPER(text) | C39: =PROPER("aarav shah") | D39: Aarav Shah | E39: Capitalise each word
A40: CONCAT | B40: =CONCAT(text1,text2,...) | C40: =CONCAT("Aarav"," ","Shah") | D40: Aarav Shah | E40: Join text without separator
A41: TEXTJOIN | B41: =TEXTJOIN(delim,skip,...) | C41: =TEXTJOIN(", ",TRUE,A1,B1) | D41: A, B | E41: Join with delimiter
A42: FIND | B42: =FIND(find, within) | C42: =FIND(".","Aarav.Shah") | D42: 6 | E42: Position of character
A43: SUBSTITUTE | B43: =SUBSTITUTE(text,old,new) | C43: =SUBSTITUTE("A.B","."," ") | D43: A B | E43: Replace text
...

Sheet 04_Date_Functions
A1: 📅 DATE FUNCTIONS — TODAY, NOW, DATE, EDATE, DATEDIF, NETWORKDAYS
A2: Date functions enable date arithmetic, tenure calculations, deadline tracking and business day counting.
A4: SAMPLE DATA — Employee Join & Project Dates
A5: Emp ID | B5: Employee Name | C5: Join Date | D5: Dept | E5: Project Start | F5: Project End | G5: Tenure (Days) | H5: Tenure (Years) | I5: Days to Delivery | J5: Working Days | K5: Status
A6: E001 | B6: Aarav Shah | C6: 43936 | D6: Sales | E6: 45301 | F6: 45473 | G6: =TODAY()-C6 | H6: =DATEDIF(C6,TODAY(),"Y")&" yrs "&DATEDIF(C6,TODAY(),"YM")&" mo" | I6: =F6-TODAY() | J6: =NETWORKDAYS(E6,F6) | K6: =IF(F6<TODAY(),"✅ Completed",IF(F6-TODAY()<=30,"⚠️ Due Soon","🔵 In Progress"))
A7: E002 | B7: Diya Sharma | C7: 44378 | D7: Marketing | E7: 45323 | F7: 45519 | G7: =TODAY()-C7 | H7: =DATEDIF(C7,TODAY(),"Y")&" yrs "&DATEDIF(C7,TODAY(),"YM")&" mo" | I7: =F7-TODAY() | J7: =NETWORKDAYS(E7,F7) | K7: =IF(F7<TODAY(),"✅ Completed",IF(F7-TODAY()<=30,"⚠️ Due Soon","🔵 In Progress"))
A8: E003 | B8: Vivaan Reddy | C8: 43485 | D8: Sales | E8: 45306 | F8: 45443 | G8: =TODAY()-C8 | H8: =DATEDIF(C8,TODAY(),"Y")&" yrs "&DATEDIF(C8,TODAY(),"YM")&" mo" | I8: =F8-TODAY() | J8: =NETWORKDAYS(E8,F8) | K8: =IF(F8<TODAY(),"✅ Completed",IF(F8-TODAY()<=30,"⚠️ Due Soon","🔵 In Progress"))
A9: E004 | B9: Ananya Nair | C9: 44870 | D9: HR | E9: 45352 | F9: 45565 | G9: =TODAY()-C9 | H9: =DATEDIF(C9,TODAY(),"Y")&" yrs "&DATEDIF(C9,TODAY(),"YM")&" mo" | I9: =F9-TODAY() | J9: =NETWORKDAYS(E9,F9) | K9: =IF(F9<TODAY(),"✅ Completed",IF(F9-TODAY()<=30,"⚠️ Due Soon","🔵 In Progress"))
A10: E005 | B10: Kabir Mehta | C10: 43263 | D10: Marketing | E10: 45311 | F10: 45493 | G10: =TODAY()-C10 | H10: =DATEDIF(C10,TODAY(),"Y")&" yrs "&DATEDIF(C10,TODAY(),"YM")&" mo" | I10: =F10-TODAY() | J10: =NETWORKDAYS(E10,F10) | K10: =IF(F10<TODAY(),"✅ Completed",IF(F10-TODAY()<=30,"⚠️ Due Soon","🔵 In Progress"))
A11: E006 | B11: Ishaan Bose | C11: 44985 | D11: Sales | E11: 45383 | F11: 45596 | G11: =TODAY()-C11 | H11: =DATEDIF(C11,TODAY(),"Y")&" yrs "&DATEDIF(C11,TODAY(),"YM")&" mo" | I11: =F11-TODAY() | J11: =NETWORKDAYS(E11,F11) | K11: =IF(F11<TODAY(),"✅ Completed",IF(F11-TODAY()<=30,"⚠️ Due Soon","🔵 In Progress"))
A12: E007 | B12: Myra Joshi | C12: 44075 | D12: HR | E12: 45337 | F12: 45535 | G12: =TODAY()-C12 | H12: =DATEDIF(C12,TODAY(),"Y")&" yrs "&DATEDIF(C12,TODAY(),"YM")&" mo" | I12: =F12-TODAY() | J12: =NETWORKDAYS(E12,F12) | K12: =IF(F12<TODAY(),"✅ Completed",IF(F12-TODAY()<=30,"⚠️ Due Soon","🔵 In Progress"))
A13: E008 | B13: Aryan Patel | C13: 44265 | D13: Sales | E13: 45361 | F13: 45626 | G13: =TODAY()-C13 | H13: =DATEDIF(C13,TODAY(),"Y")&" yrs "&DATEDIF(C13,TODAY(),"YM")&" mo" | I13: =F13-TODAY() | J13: =NETWORKDAYS(E13,F13) | K13: =IF(F13<TODAY(),"✅ Completed",IF(F13-TODAY()<=30,"⚠️ Due Soon","🔵 In Progress"))
A14: E009 | B14: Kiara Gupta | C14: 42972 | D14: Marketing | E14: 45296 | F14: 45458 | G14: =TODAY()-C14 | H14: =DATEDIF(C14,TODAY(),"Y")&" yrs "&DATEDIF(C14,TODAY(),"YM")&" mo" | I14: =F14-TODAY() | J14: =NETWORKDAYS(E14,F14) | K14: =IF(F14<TODAY(),"✅ Completed",IF(F14-TODAY()<=30,"⚠️ Due Soon","🔵 In Progress"))
A15: E010 | B15: Reyansh Singh | C15: 44695 | D15: Sales | E15: 45402 | F15: 45657 | G15: =TODAY()-C15 | H15: =DATEDIF(C15,TODAY(),"Y")&" yrs "&DATEDIF(C15,TODAY(),"YM")&" mo" | I15: =F15-TODAY() | J15: =NETWORKDAYS(E15,F15) | K15: =IF(F15<TODAY(),"✅ Completed",IF(F15-TODAY()<=30,"⚠️ Due Soon","🔵 In Progress"))
A17: DATE FUNCTION REFERENCE
A18: Function | B18: Syntax | C18: Example | D18: Live Result | E18: What It Returns
A19: TODAY | B19: =TODAY() | C19: =TODAY() | D19: =TODAY() | E19: Today's date (auto-updates)
A20: NOW | B20: =NOW() | C20: =NOW() | D20: =NOW() | E20: Current date + time
A21: DATE | B21: =DATE(year,month,day) | C21: =DATE(2024,8,15) | D21: =DATE(2024,8,15) | E21: Construct a date from parts
A22: EDATE | B22: =EDATE(start_date, months) | C22: =EDATE(TODAY(),3) | D22: =EDATE(TODAY(),3) | E22: Date n months from start
A23: DATEDIF | B23: =DATEDIF(start,end,"Y"/"M"/"D") | C23: =DATEDIF(DATE(2020,4,15),TODAY(),"Y") | D23: =DATEDIF(DATE(2020,4,15),TODAY(),"Y") | E23: Difference in years, months, days
A24: NETWORKDAYS | B24: =NETWORKDAYS(start,end,[holidays]) | C24: =NETWORKDAYS(DATE(2024,1,1),DATE(2024,12,31)) | D24: =NETWORKDAYS(DATE(2024,1,1),DATE(2024,12,31)) | E24: Working days between dates
A25: YEAR/MONTH/DAY | B25: =YEAR(date), =MONTH(date), =DAY(date) | C25: =YEAR(TODAY()) | D25: =YEAR(TODAY()) | E25: Extract year/month/day part
A26: EOMONTH | B26: =EOMONTH(start_date, months) | C26: =EOMONTH(TODAY(),0) | D26: =EOMONTH(TODAY(),0) | E26: Last day of the month
A28: ✏️ EXERCISE — Date calculations on employee and project data
A29: Q1: Calculate how many days each employee has been working (=TODAY()-JoinDate) → verify column G
A30: Q2: Use DATEDIF with 'YM' to get months AFTER the last full year of service
A31: Q3: Use EDATE to calculate the contract renewal date (6 months after join date) → column L
A32: Q4: Count how many projects are 'Due Soon' (delivery within 30 days) using COUNTIF on column K
A33: Q5: Use NETWORKDAYS to count working days remaining for each project
A34: Q6: Use YEAR(JoinDate) to group employees by the year they joined → COUNTIF by year
A35: Q7: Find the longest-serving employee using MIN(JoinDate) and DATEDIF
A36: Q8: Use EOMONTH(ProjectEnd,0) to confirm the project ends on the last day of the month
A37: 💡 DATEDIF is undocumented in Excel help but fully functional. Use 'Y' for years, 'M' for months, 'D' for days, 'YM' for months after last full year.

Sheet 05_Math_Stat_Functions
A1: 🔢 MATH & STAT FUNCTIONS — SUM, AVERAGE, COUNT, COUNTA, ROUND, INT, MOD
A2: Math and statistical functions form the backbone of quantitative analysis in Excel.
A4: SAMPLE DATA — Product Sales Data
A5: Product ID | B5: Product Name | C5: Category | D5: Unit Price (₹) | E5: Units Sold | F5: Revenue (₹) | G5: Discount % | H5: Net Revenue | I5: Tax (18%) | J5: Final Price
A6: P001 | B6: iPhone 15 | C6: Electronics | D6: 89999 | E6: 45 | F6: =D6*E6 | G6: 0.1 | H6: =ROUND(F6*(1-G6),0) | I6: =ROUND(H6*0.18,0) | J6: =H6+I6
A7: P002 | B7: Samsung S24 | C7: Electronics | D7: 74999 | E7: 62 | F7: =D7*E7 | G7: 0.08 | H7: =ROUND(F7*(1-G7),0) | I7: =ROUND(H7*0.18,0) | J7: =H7+I7
A8: P003 | B8: OnePlus 12 | C8: Electronics | D8: 64999 | E8: 38 | F8: =D8*E8 | G8: 0.12 | H8: =ROUND(F8*(1-G8),0) | I8: =ROUND(H8*0.18,0) | J8: =H8+I8
A9: P004 | B9: Nike Air Max | C9: Footwear | D9: 12999 | E9: 120 | F9: =D9*E9 | G9: 0.15 | H9: =ROUND(F9*(1-G9),0) | I9: =ROUND(H9*0.18,0) | J9: =H9+I9
A10: P005 | B10: Adidas Ultra | C10: Footwear | D10: 9999 | E10: 85 | F10: =D10*E10 | G10: 0.1 | H10: =ROUND(F10*(1-G10),0) | I10: =ROUND(H10*0.18,0) | J10: =H10+I10
A11: P006 | B11: Levi's Jeans | C11: Clothing | D11: 3499 | E11: 210 | F11: =D11*E11 | G11: 0.2 | H11: =ROUND(F11*(1-G11),0) | I11: =ROUND(H11*0.18,0) | J11: =H11+I11
A12: P007 | B12: H&M Shirt | C12: Clothing | D12: 1299 | E12: 340 | F12: =D12*E12 | G12: 0.18 | H12: =ROUND(F12*(1-G12),0) | I12: =ROUND(H12*0.18,0) | J12: =H12+I12
A13: P008 | B13: Boat Earbuds | C13: Electronics | D13: 2499 | E13: 580 | F13: =D13*E13 | G13: 0.05 | H13: =ROUND(F13*(1-G13),0) | I13: =ROUND(H13*0.18,0) | J13: =H13+I13
A14: P009 | B14: Dell Laptop | C14: Electronics | D14: 65999 | E14: 28 | F14: =D14*E14 | G14: 0.07 | H14: =ROUND(F14*(1-G14),0) | I14: =ROUND(H14*0.18,0) | J14: =H14+I14
A15: P010 | B15: HP Printer | C15: Electronics | D15: 15999 | E15: 42 | F15: =D15*E15 | G15: 0.08 | H15: =ROUND(F15*(1-G15),0) | I15: =ROUND(H15*0.18,0) | J15: =H15+I15
A16: P011 | B16: Woodland Shoe | C16: Footwear | D16: 7499 | E16: 95 | F16: =D16*E16 | G16: 0.12 | H16: =ROUND(F16*(1-G16),0) | I16: =ROUND(H16*0.18,0) | J16: =H16+I16
A17: P012 | B17: Zara Dress | C17: Clothing | D17: 4999 | E17: 180 | F17: =D17*E17 | G17: 0.15 | H17: =ROUND(F17*(1-G17),0) | I17: =ROUND(H17*0.18,0) | J17: =H17+I17
... A20: P015 | B20: Fossil Watch | C20: Accessories | D20: 12999 | E20: 68 | F20: =D20*E20 | G20: 0.08 | H20: =ROUND(F20*(1-G20),0) | I20: =ROUND(H20*0.18,0) | J20: =H20+I20
A22: SUMMARY STATISTICS — All Math/Stat Functions Applied
A23: Metric | B23: Formula | C23: Result | D23: Description
A24: Total Revenue | B24: =SUM(F6:F20) | C24: =SUM(F6:F20) | D24: Sum all revenue
A25: Total Net Revenue | B25: =SUM(H6:H20) | C25: =SUM(H6:H20) | D25: Sum discounted revenue
A26: Average Unit Price | B26: =AVERAGE(D6:D20) | C26: =AVERAGE(D6:D20) | D26: Mean unit price
A27: Average Units Sold | B27: =ROUND(AVERAGE(E6:E20),0) | C27: =ROUND(AVERAGE(E6:E20),0) | D27: Mean units (rounded)
A28: Count of Products | B28: =COUNT(E6:E20) | C28: =COUNT(E6:E20) | D28: Count numeric cells
A29: Count Non-Empty Names | B29: =COUNTA(B6:B20) | C29: =COUNTA(B6:B20) | D29: Count non-empty cells
A30: Max Revenue Product | B30: =MAX(F6:F20) | C30: =MAX(F6:F20) | D30: Highest revenue row
A31: Min Revenue Product | B31: =MIN(F6:F20) | C31: =MIN(F6:F20) | D31: Lowest revenue row
A32: ROUND(Tax, -3) | B32: =ROUND(SUM(I6:I20),-3) | C32: =ROUND(SUM(I6:I20),-3) | D32: Round to nearest 1000
A33: INT of Avg Price | B33: =INT(AVERAGE(D6:D20)) | C33: =INT(AVERAGE(D6:D20)) | D33: Integer part of average
A34: MOD(Units,10) | B34: =MOD(SUM(E6:E20),10) | C34: =MOD(SUM(E6:E20),10) | D34: Remainder of total units ÷ 10
A35: Electronics Revenue | B35: =SUMIF(C6:C20,"Electronics",F6:F20) | C35: =SUMIF(C6:C20,"Electronics",F6:F20) | D35: Category-specific sum
A37: ✏️ EXERCISE — Math/Stat formulas on product data
A38: Q1: Calculate total revenue for each Category using SUMIF (Electronics, Footwear, Clothing, Accessories)
A39: Q2: Use AVERAGEIF to find the average discount % for Electronics products
A40: Q3: Use COUNTIF to count how many products have more than 100 units sold
A41: Q4: Use INT to calculate how many full thousands are in each product's revenue (=INT(Revenue/1000))
A42: Q5: Use MOD to flag products where Units Sold is divisible by 5 → MOD(E,5)=0
A43: Q6: Use ROUND with -2 to round all prices to nearest 100
A44: Q7: Use LARGE(range,1), LARGE(range,2), LARGE(range,3) to find Top 3 revenues
A45: Q8: Calculate the Gross Profit Margin: (Net Revenue - Cost) / Revenue where Cost = Price * 0.6
...

Sheet 06_Lookup_VLOOKUP_HLOOKUP
A1: 🔍 LOOKUP FUNCTIONS — VLOOKUP, HLOOKUP (+ XLOOKUP Preview)
A2: Lookup functions find and retrieve data from tables. VLOOKUP searches vertically; HLOOKUP searches horizontally.
A4: EMPLOYEE LOOKUP TABLE (Reference)
A5: Emp ID | B5: Name | C5: Dept | D5: City | E5: Salary (₹) | F5: Rating
A6: E001 | B6: Aarav Shah | C6: Sales | D6: Mumbai | E6: 55000 | F6: A
A7: E002 | B7: Diya Sharma | C7: Marketing | D7: Delhi | E7: 48000 | F7: B+
A8: E003 | B8: Vivaan Reddy | C8: Sales | D8: Bengaluru | E8: 62000 | F8: A+
A9: E004 | B9: Ananya Nair | C9: HR | D9: Hyderabad | E9: 42000 | F9: B
A10: E005 | B10: Kabir Mehta | C10: Marketing | D10: Chennai | E10: 51000 | F10: A
A11: E006 | B11: Ishaan Bose | C11: Sales | D11: Kolkata | E11: 68000 | F11: A+
A12: E007 | B12: Myra Joshi | C12: HR | D12: Pune | E12: 38000 | F12: C
A13: E008 | B13: Aryan Patel | C13: Sales | D13: Ahmedabad | E13: 57000 | F13: A
A14: E009 | B14: Kiara Gupta | C14: Marketing | D14: Jaipur | E14: 44000 | F14: B+
A15: E010 | B15: Reyansh Singh | C15: Sales | D15: Lucknow | E15: 59000 | F15: A
A17: VLOOKUP — Vertical Lookup (search a column, return from same row)
A18: Lookup Value | B18: VLOOKUP Formula | C18: Col Index | D18: Result | E18: Explanation
A19: E003 | B19: =VLOOKUP("E003",$A$6:$F$15,2,FALSE) | C19: 2 | D19: =VLOOKUP("E003",$A$6:$F$15,2,FALSE) | E19: Get Name for E003
A20: E006 | B20: =VLOOKUP("E006",$A$6:$F$15,3,FALSE) | C20: 3 | D20: =VLOOKUP("E006",$A$6:$F$15,3,FALSE) | E20: Get Dept for E006
A21: E001 | B21: =VLOOKUP("E001",$A$6:$F$15,5,FALSE) | C21: 5 | D21: =VLOOKUP("E001",$A$6:$F$15,5,FALSE) | E21: Get Salary for E001
A22: E009 | B22: =VLOOKUP("E009",$A$6:$F$15,4,FALSE) | C22: 4 | D22: =VLOOKUP("E009",$A$6:$F$15,4,FALSE) | E22: Get City for E009
A23: E010 | B23: =IFERROR(VLOOKUP("E010",$A$6:$F$15,6,FALSE),"Not Found") | C23: 6 | D23: =IFERROR(VLOOKUP("E010",$A$6:$F$15,6,FALSE),"Not Found") | E23: Rating with IFERROR
A24: E999 | B24: =IFERROR(VLOOKUP("E999",$A$6:$F$15,2,FALSE),"Not Found") | C24: 2 | D24: =IFERROR(VLOOKUP("E999",$A$6:$F$15,2,FALSE),"Not Found") | E24: Handles missing ID gracefully
A26: HLOOKUP — Horizontal Lookup (search a row, return from same column)
A28: Metric | B28: Jan | C28: Feb | D28: Mar | E28: Apr | F28: May | G28: Jun
A29: Sales (₹) | B29: 450000 | C29: 380000 | D29: 520000 | E29: 490000 | F29: 610000 | G29: 575000
A30: Target (₹) | B30: 500000 | C30: 400000 | D30: 500000 | E30: 500000 | F30: 600000 | G30: 600000
A31: % Achieved | B31: =B30/B29 | C31: =B30/B29 | D31: =B30/B29 | E31: =B30/B29 | F31: =B30/B29 | G31: =B30/B29
A32: 💡 HLOOKUP syntax: =HLOOKUP(lookup_val, table_array, row_index, FALSE) → Searches top row, returns from row_index below
A33: Lookup Month | B33: HLOOKUP Formula | C33: Result | D33: Description
A34: Mar | B34: =HLOOKUP("Mar",B28:G29,2,FALSE) | C34: =HLOOKUP("Mar",B28:G29,2,FALSE) | D34: Return March Sales
A35: May | B35: =HLOOKUP("May",B28:G30,2,FALSE) | C35: =HLOOKUP("May",B28:G30,2,FALSE) | D35: Return May Target
A37: VLOOKUP vs XLOOKUP — Key Differences (Preview)
A38: Feature | B38: VLOOKUP | C38: XLOOKUP
A39: Direction | B39: Only searches LEFT column | C39: Can search any column
A40: Return Column | B40: Column index number (e.g., 3) | C40: Direct range reference (e.g., C:C)
A41: Not Found | B41: Returns #N/A error | C41: Built-in if_not_found argument
A42: Multiple Returns | B42: One column at a time | C42: Can return entire row/column
A43: Wildcards | B43: Supported | C43: Supported + Regex options
A44: Syntax Length | B44: =VLOOKUP(val,range,col,FALSE) | C44: =XLOOKUP(val,lookup,return,"not found")
A46: ✏️ EXERCISE — Practice VLOOKUP and HLOOKUP
...

Sheet 07_Conditional_Formatting
A1: 🎨 CONDITIONAL FORMATTING — Rules, Color Scales, Data Bars, Icon Sets, Custom Formulas
A2: Conditional formatting automatically changes cell appearance based on values or formulas — turning numbers into instant visuals.
A4: SAMPLE DATA — Regional Sales Performance
A5: Region | B5: Q1 Sales | C5: Q2 Sales | D5: Q3 Sales | E5: Q4 Sales | F5: Total | G5: Rank | H5: % of Target | I5: Bonus?
A6: North - Delhi | B6: 285000 | C6: 310000 | D6: 295000 | E6: 340000 | F6: =B6+C6+D6+E6 | G6: =RANK(F6,F6:F13,0) | H6: =F6/3000000 | I6: =IF(H6>=1,"✅ Yes","❌ No")
A7: South - Chennai | B7: 220000 | C7: 198000 | D7: 245000 | E7: 267000 | F7: =B7+C7+D7+E7 | G7: =RANK(F7,F6:F13,0) | H7: =F7/2500000 | I7: =IF(H7>=1,"✅ Yes","❌ No")
A8: East - Kolkata | B8: 175000 | C8: 188000 | D8: 195000 | E8: 210000 | F8: =B8+C8+D8+E8 | G8: =RANK(F8,F6:F13,0) | H8: =F8/2200000 | I8: =IF(H8>=1,"✅ Yes","❌ No")
A9: West - Mumbai | B9: 350000 | C9: 390000 | D9: 365000 | E9: 420000 | F9: =B9+C9+D9+E9 | G9: =RANK(F9,F6:F13,0) | H9: =F9/3500000 | I9: =IF(H9>=1,"✅ Yes","❌ No")
A10: Central - Bhopal | B10: 145000 | C10: 162000 | D10: 158000 | E10: 175000 | F10: =B10+C10+D10+E10 | G10: =RANK(F10,F6:F13,0) | H10: =F10/1800000 | I10: =IF(H10>=1,"✅ Yes","❌ No")
A11: NE - Guwahati | B11: 95000 | C11: 108000 | D11: 115000 | E11: 125000 | F11: =B11+C11+D11+E11 | G11: =RANK(F11,F6:F13,0) | H11: =F11/1200000 | I11: =IF(H11>=1,"✅ Yes","❌ No")
A12: NW - Jaipur | B12: 188000 | C12: 202000 | D12: 198000 | E12: 215000 | F12: =B12+C12+D12+E12 | G12: =RANK(F12,F6:F13,0) | H12: =F12/2000000 | I12: =IF(H12>=1,"✅ Yes","❌ No")
A13: South2 - Pune | B13: 265000 | C13: 278000 | D13: 292000 | E13: 315000 | F13: =B13+C13+D13+E13 | G13: =RANK(F13,F6:F13,0) | H13: =F13/2800000 | I13: =IF(H13>=1,"✅ Yes","❌ No")
A15: HOW TO APPLY EACH TYPE — Step-by-Step Guide
A16: CF Type | B16: Where to Apply | C16: Steps (Home → Conditional Formatting)
A17: Greater Than | B17: Sales columns | C17: Highlight Cell Rules → Greater Than → type value → choose colour
A18: Top 10% | B18: Total column | C18: Top/Bottom Rules → Top 10% → OK
A19: Duplicate Values | B19: Any column | C19: Highlight Cell Rules → Duplicate Values → choose colour
A20: Color Scales | B20: Total column (F) | C20: Color Scales → choose Red-Yellow-Green (already applied above!)
A21: Data Bars | B21: Q1 column (B) | C21: Data Bars → choose colour (already applied above!)
A22: Icon Sets | B22: % of Target | C22: Icon Sets → 3 Arrows → values above 100% get green arrow
A23: Custom Formula | B23: Entire row | C23: New Rule → Use formula: =$H6>=1 → green fill → applies to full row
A25: ✏️ EXERCISE — Apply all 7 types of conditional formatting to the data above
A26: Q1: Highlight Q3 sales > 300,000 with green fill and bold text
A27: Q2: Apply Top 10% rule to the Total column — mark the top regions
A28: Q3: Apply a Red-Yellow-Green color scale to all 4 quarterly columns (B:E)
A29: Q4: Add data bars to the % of Target column (H) to see achievement visually
A30: Q5: Apply a custom formula rule: highlight the ENTIRE ROW in green if % of Target >= 100%
A31: Q6: Add Icon Sets (traffic lights) to the Bonus column: ✅=green, ❌=red
A32: Q7: Use 'Duplicate Values' rule on the Region column to check for accidental duplicates
A33: Q8: Use 'Bottom 3' rule to highlight the lowest-performing 3 regions in light red
A34: 💡 Custom formula-based rules are the most powerful CF type. Use =$H6>=1 (lock column H, unlock row) to apply to an entire row.

Sheet 08_Charts_Column_Bar_Line_Pie
A1: 📊 CHARTS — Column, Bar, Line, Pie, Combo Charts & Choosing the Right Chart
A2: Charts translate numbers into visuals. Choosing the right chart type is as important as the formula itself.
A4: DATA SET 1 — Monthly Revenue & Target (Use for Column / Line / Combo Chart)
A5: Month | B5: Revenue (₹) | C5: Target (₹) | D5: Growth %
A6: Jan | B6: 285000 | C6: 300000 | D6: —
A7: Feb | B7: 310000 | C7: 300000 | D7: =IF(B6=0,"",ROUND((B7-B6)/B6*100,1))
A8: Mar | B8: 295000 | C8: 320000 | D8: =IF(B7=0,"",ROUND((B8-B7)/B7*100,1))
A9: Apr | B9: 340000 | C9: 350000 | D9: =IF(B8=0,"",ROUND((B9-B8)/B8*100,1))
A10: May | B10: 390000 | C10: 370000 | D10: =IF(B9=0,"",ROUND((B10-B9)/B9*100,1))
A11: Jun | B11: 375000 | C11: 380000 | D11: =IF(B10=0,"",ROUND((B11-B10)/B10*100,1))
A12: Jul | B12: 420000 | C12: 400000 | D12: =IF(B11=0,"",ROUND((B12-B11)/B11*100,1))
A13: Aug | B13: 405000 | C13: 410000 | D13: =IF(B12=0,"",ROUND((B13-B12)/B12*100,1))
A14: Sep | B14: 450000 | C14: 440000 | D14: =IF(B13=0,"",ROUND((B14-B13)/B13*100,1))
A15: Oct | B15: 480000 | C15: 470000 | D15: =IF(B14=0,"",ROUND((B15-B14)/B14*100,1))
A16: Nov | B16: 510000 | C16: 500000 | D16: =IF(B15=0,"",ROUND((B16-B15)/B15*100,1))
A17: Dec | B17: 540000 | C17: 530000 | D17: =IF(B16=0,"",ROUND((B17-B16)/B16*100,1))
A19: DATA SET 2 — Sales by Category (Use for Pie / Doughnut Chart)
A20: Category | B20: Sales (₹) | C20: % Share
A21: Electronics | B21: 1850000 | C21: =B21/SUM($B$21:$B$25)
A22: Footwear | B22: 620000 | C22: =B22/SUM($B$21:$B$25)
A23: Clothing | B23: 480000 | C23: =B23/SUM($B$21:$B$25)
A24: Accessories | B24: 250000 | C24: =B24/SUM($B$21:$B$25)
A25: Home & Living | B25: 380000 | C25: =B25/SUM($B$21:$B$25)
A27: DATA SET 3 — City-wise Sales (Use for Bar / Horizontal Chart)
A28: City | B28: Sales (₹) | C28: Employees | D28: Per Head (₹)
A29: Mumbai | B29: 850000 | C29: 15 | D29: =ROUND(B29/C29,0)
A30: Delhi | B30: 720000 | C30: 13 | D30: =ROUND(B30/C30,0)
A31: Bengaluru | B31: 690000 | C31: 12 | D31: =ROUND(B31/C31,0)
A32: Hyderabad | B32: 540000 | C32: 10 | D32: =ROUND(B32/C32,0)
A33: Chennai | B33: 480000 | C33: 9 | D33: =ROUND(B33/C33,0)
A34: Kolkata | B34: 420000 | C34: 8 | D34: =ROUND(B34/C34,0)
A35: Pune | B35: 380000 | C35: 7 | D35: =ROUND(B35/C35,0)
A36: Ahmedabad | B36: 310000 | C36: 6 | D36: =ROUND(B36/C36,0)
A38: CHART SELECTION GUIDE — Which Chart for Which Data?
A39: Chart Type | B39: Best Used For | C39: Example Use Case | D39: Avoid When
A40: Column Chart | B40: Comparing values across categories | C40: Monthly revenue comparison, city-wise sales | D40: Too many categories (>10)
A41: Bar Chart | B41: Same as column but horizontal | C41: City ranking, product comparison with long names | D41: Showing time trends
A42: Line Chart | B42: Showing trends over time | C42: Monthly revenue trend, stock price movement | D42: Comparing categories
A43: Pie Chart | B43: Parts of a whole (proportions) | C43: Market share %, category split | D43: More than 6 slices or time data
A44: Combo Chart | B44: Two measures with different scales | C44: Revenue (bars) + Growth% (line) | D44: Simple single-metric data
...

Sheet 09_Pivot_Tables
A1: 🔄 PIVOT TABLES — Create, Summarize, Group, Filter, Drill-Down
A2: Pivot Tables are the most powerful data analysis tool in Excel — summarise thousands of rows in seconds without formulas.
A4: SOURCE DATA — Use this structured data to create Pivot Tables (Ctrl+T first, then Insert → PivotTable)
A5: Order ID | B5: Date | C5: Sales Rep | D5: Region | E5: Category | F5: Product | G5: Units | H5: Unit Price (₹) | I5: Revenue (₹) | J5: Discount% | K5: Net Revenue
A6: ORD001 | B6: 45296 | C6: Aarav Shah | D6: North | E6: Electronics | F6: iPhone 15 | G6: 2 | H6: 89999 | I6: =G6*H6 | J6: 0.1 | K6: =ROUND(I6*(1-J6),0)
A7: ORD002 | B7: 45299 | C7: Diya Sharma | D7: South | E7: Clothing | F7: Levi's Jeans | G7: 5 | H7: 3499 | I7: =G7*H7 | J7: 0.2 | K7: =ROUND(I7*(1-J7),0)
A8: ORD003 | B8: 45303 | C8: Vivaan Reddy | D8: West | E8: Electronics | F8: Samsung S24 | G8: 3 | H8: 74999 | I8: =G8*H8 | J8: 0.08 | K8: =ROUND(I8*(1-J8),0)
A9: ORD004 | B9: 45306 | C9: Ananya Nair | D9: East | E9: Footwear | F9: Nike Air Max | G9: 4 | H9: 12999 | I9: =G9*H9 | J9: 0.15 | K9: =ROUND(I9*(1-J9),0)
A10: ORD005 | B10: 45311 | C10: Kabir Mehta | D10: North | E10: Electronics | F10: Boat Earbuds | G10: 10 | H10: 2499 | I10: =G10*H10 | J10: 0.05 | K10: =ROUND(I10*(1-J10),0)
A11: ORD006 | B11: 45325 | C11: Aarav Shah | D11: North | E11: Footwear | F11: Adidas Ultra | G11: 6 | H11: 9999 | I11: =G11*H11 | J11: 0.1 | K11: =ROUND(I11*(1-J11),0)
A12: ORD007 | B12: 45329 | C12: Ishaan Bose | D12: East | E12: Electronics | F12: Dell Laptop | G12: 1 | H12: 65999 | I12: =G12*H12 | J12: 0.07 | K12: =ROUND(I12*(1-J12),0)
A13: ORD008 | B13: 45336 | C13: Myra Joshi | D13: South | E13: Clothing | F13: Zara Dress | G13: 3 | H13: 4999 | I13: =G13*H13 | J13: 0.15 | K13: =ROUND(I13*(1-J13),0)
A14: ORD009 | B14: 45340 | C14: Aryan Patel | D14: West | E14: Electronics | F14: Sony Headphone | G14: 5 | H14: 8999 | I14: =G14*H14 | J14: 0.1 | K14: =ROUND(I14*(1-J14),0)
A15: ORD010 | B15: 45344 | C15: Kiara Gupta | D15: North | E15: Clothing | F15: H&M Shirt | G15: 8 | H15: 1299 | I15: =G15*H15 | J15: 0.18 | K15: =ROUND(I15*(1-J15),0)
A16: ORD011 | B16: 45356 | C16: Reyansh Singh | D16: South | E16: Electronics | F16: OnePlus 12 | G16: 2 | H16: 64999 | I16: =G16*H16 | J16: 0.12 | K16: =ROUND(I16*(1-J16),0)
A17: ORD012 | B17: 45360 | C17: Ira Desai | D17: West | E17: Footwear | F17: Woodland Shoe | G17: 3 | H17: 7499 | I17: =G17*H17 | J17: 0.12 | K17: =ROUND(I17*(1-J17),0)
... A25: ORD020 | B25: 45407 | C25: Kabir Mehta | D25: East | E25: Footwear | F25: Adidas Ultra | G25: 4 | H25: 9999 | I25: =G25*H25 | J25: 0.1 | K25: =ROUND(I25*(1-J25),0)
A27: HOW TO BUILD EACH PIVOT TABLE — Step-by-Step
A28: Pivot Table Goal | B28: Pivot Field Setup | C28: What You Learn
A29: Revenue by Region | B29: Rows: Region | Values: Sum of Revenue | C29: → See which region generates most revenue
A30: Revenue by Category & Region | B30: Rows: Category | Columns: Region | Values: Sum of Net Revenue | C30: → Cross-tab showing category performance per region
A31: Monthly Revenue Trend | B31: Rows: Date (group by Month) | Values: Sum of Revenue | C31: → Right-click date → Group → Months
A32: Top Sales Reps | B32: Rows: Sales Rep | Values: Sum of Revenue, Count of Orders | C32: → Sort by Revenue descending → see top performers
A33: Count vs Sum | B33: Rows: Category | Values: Count of Orders, Sum of Units, Sum of Revenue | C33: → Summarisation techniques beyond just Sum
A34: Average Order Value | B34: Rows: Region | Values: Average of Revenue | C34: → Change Value Field Settings: Sum → Average
A36: ✏️ EXERCISE — Create 6 Pivot Tables from the source data above
A37: Q1: Select the data (A5:K25) → Ctrl+T → Insert → PivotTable → New Sheet → build Revenue by Region
A38: Q2: Add Category to Columns area → create a cross-tab of Revenue by Region AND Category
A39: Q3: Right-click the Date field → Group → select Months → create monthly trend
A40: Q4: Add a Slicer: PivotTable Analyze → Insert Slicer → Region → filter with one click
A41: Q5: Change Sum to Average (right-click value → Value Field Settings → Average)
A42: Q6: Add 'Show Values As' → % of Grand Total to see proportional contribution
A43: Q7: Double-click a value cell in the pivot to drill down into the underlying rows
A44: Q8: Sort the Sales Rep pivot by Revenue descending to rank top performers
A45: Q9: Insert a PivotChart (Bar) from the Region pivot — link chart to slicer
A46: 💡 Pivot Tables are 100% point-and-click. No formulas needed. They update instantly with Refresh when source data changes.

Sheet 10_XLOOKUP_Advanced
A1: 🚀 XLOOKUP — Syntax, Vertical & Horizontal, IFERROR, Wildcard, 2-Way Lookup, vs VLOOKUP
A2: XLOOKUP is the modern replacement for VLOOKUP. More flexible, more powerful, and easier to read.
A4: EMPLOYEE LOOKUP TABLE (Reference — same data as Sheet 6)
A5: Emp ID | B5: Name | C5: Dept | D5: City | E5: Salary (₹) | F5: Rating | G5: Years Exp
A6: E001 | B6: Aarav Shah | C6: Sales | D6: Mumbai | E6: 55000 | F6: A | G6: 4
A7: E002 | B7: Diya Sharma | C7: Marketing | D7: Delhi | E7: 48000 | F7: B+ | G7: 3
A8: E003 | B8: Vivaan Reddy | C8: Sales | D8: Bengaluru | E8: 62000 | F8: A+ | G8: 5
A9: E004 | B9: Ananya Nair | C9: HR | D9: Hyderabad | E9: 42000 | F9: B | G9: 2
A10: E005 | B10: Kabir Mehta | C10: Marketing | D10: Chennai | E10: 51000 | F10: A | G10: 3
A11: E006 | B11: Ishaan Bose | C11: Sales | D11: Kolkata | E11: 68000 | F11: A+ | G11: 7
A12: E007 | B12: Myra Joshi | C12: HR | D12: Pune | E12: 38000 | F12: C | G12: 1
A13: E008 | B13: Aryan Patel | C13: Sales | D13: Ahmedabad | E13: 57000 | F13: A | G13: 4
A14: E009 | B14: Kiara Gupta | C14: Marketing | D14: Jaipur | E14: 44000 | F14: B+ | G14: 2
A15: E010 | B15: Reyansh Singh | C15: Sales | D15: Lucknow | E15: 59000 | F15: A | G15: 5
A17: XLOOKUP EXAMPLES — All Use Cases with Live Results
A18: Use Case | B18: XLOOKUP Formula | C18: Result | D18: Explanation
A19: Basic Lookup — Get Name | B19: =XLOOKUP("E003",A6:A15,B6:B15) | C19: =XLOOKUP("E003",A6:A15,B6:B15) | D19: Find E003's name
A20: Get Salary for E006 | B20: =XLOOKUP("E006",A6:A15,E6:E15) | C20: =XLOOKUP("E006",A6:A15,E6:E15) | D20: Return salary (column 5 in VLOOKUP, direct range in XLOOKUP)
A21: With Not Found Message | B21: =XLOOKUP("E999",A6:A15,B6:B15,"Employee Not Found") | C21: =XLOOKUP("E999",A6:A15,B6:B15,"Employee Not Found") | D21: 4th argument handles #N/A automatically
A22: Lookup from Right | B22: =XLOOKUP("Mumbai",D6:D15,B6:B15,"Not Found") | C22: =XLOOKUP("Mumbai",D6:D15,B6:B15,"Not Found") | D22: Search City (right col) → return Name (left col) — VLOOKUP cannot do this!
A23: Wildcard Lookup | B23: =XLOOKUP("Aarav*",B6:B15,E6:E15,"Not Found",2) | C23: =XLOOKUP("Aarav*",B6:B15,E6:E15,"Not Found",2) | D23: 5th arg=2 enables wildcards. * matches any characters
A24: Return Multiple Columns | B24: =XLOOKUP("E008",A6:A15,B6:D15,"Not Found") | C24: =XLOOKUP("E008",A6:A15,B6:D15,"Not Found") | D24: Returns Name, Dept, City all at once (spills into 3 cells)
A25: Last Match | B25: =XLOOKUP("Sales",C6:C15,B6:B15,"None",0,-1) | C25: =XLOOKUP("Sales",C6:C15,B6:B15,"None",0,-1) | D25: 6th arg=-1 searches from bottom up → last Sales employee
A27: TWO-WAY LOOKUP — XLOOKUP inside XLOOKUP (Row AND Column)
A28: 💡 Nested XLOOKUP: =XLOOKUP(row_val, row_range, XLOOKUP(col_val, col_range, data_matrix)) — finds intersection of row and column
B29: Q1 | C29: Q2 | D29: Q3 | E29: Q4
A30: Aarav Shah | B30: 285000 | C30: 310000 | D30: 295000 | E30: 340000
A31: Diya Sharma | B31: 198000 | C31: 220000 | D31: 245000 | E31: 267000
A32: Vivaan Reddy | B32: 310000 | C32: 290000 | D32: 330000 | E32: 385000
A33: Ananya Nair | B33: 175000 | C33: 188000 | D33: 195000 | E33: 210000
A34: Kabir Mehta | B34: 260000 | C34: 278000 | D34: 292000 | E34: 315000
A35: 2-Way Lookup Formula | B35: =XLOOKUP("Vivaan Reddy",$A$30:$A$34,XLOOKUP("Q3",$B$29:$E$29,$B$30:$E$34)) | C35: =XLOOKUP("Vivaan Reddy",$A$30:$A$34,XLOOKUP("Q3",$B$29:$E$29,$B$30:$E$34)) | D35: Returns Vivaan Reddy's Q3 sales from the matrix → intersection of row & column
A37: XLOOKUP vs VLOOKUP vs INDEX-MATCH — Complete Comparison
A38: Scenario | B38: VLOOKUP | C38: INDEX-MATCH | D38: XLOOKUP
A39: Find name by ID | B39: =VLOOKUP("E003",A:F,2,0) | C39: =INDEX(B:B,MATCH("E003",A:A,0)) | D39: =XLOOKUP("E003",A:A,B:B)
A40: Left lookup (City→Name) | B40: ❌ Cannot look left | C40: =INDEX(B:B,MATCH("Mumbai",D:D,0)) | D40: =XLOOKUP("Mumbai",D:D,B:B)
A41: Not found handling | B41: =IFERROR(VLOOKUP(...),"No") | C41: =IFERROR(INDEX(MATCH(...)),"No") | D41: =XLOOKUP(...,"No")
A42: Multiple columns | B42: Need 3 separate VLOOKUPs | C42: Need INDEX with multiple ranges | D42: =XLOOKUP("E003",A:A,B:D)
A43: Wildcard search | B43: =VLOOKUP("A*",A:F,2,0) | C43: Complex formula needed | D43: =XLOOKUP("A*",B:B,E:E,"",2)
A45: ✏️ EXERCISE — Practice all XLOOKUP variations
...

Sheet 11_Advanced_Integration
A1: ⚡ ADVANCED INTEGRATION — XLOOKUP + Pivot + Cross-Sheet + Nested Formulas
A2: Real-world analytics combines multiple tools. This sheet shows advanced patterns used in professional dashboards.
A4: SALES PERFORMANCE DASHBOARD — Advanced Summarization
A6: Total Revenue | B6: Net Revenue | C6: Avg Order | D6: Top Region | E6: Total Orders | F6: Best Month
A7: ='09_Pivot_Tables'!I6+'09_Pivot_Tables'!I7+'09_Pivot_Tables'!I8 | B7: ='09_Pivot_Tables'!K6+'09_Pivot_Tables'!K7+'09_Pivot_Tables'!K8 | C7: =AVERAGE('09_Pivot_Tables'!I6:I25) | D7: =TEXT(MAX('09_Pivot_Tables'!I6:I25),"₹#,##0") | E7: =COUNTA('09_Pivot_Tables'!A6:A25) | F7: =TEXT(TODAY(),"MMM YYYY")
A9: ADVANCED FORMULA PATTERNS — Nested & Cross-Sheet
A10: Pattern | B10: Formula | C10: When to Use
A11: XLOOKUP + IF | B11: =IF(XLOOKUP("E003",'10_XLOOKUP_Advanced'!A6:A15,'10_XLOOKUP_Advanced'!F6:F15)="A+","Bonus Eligible","Standard") | C11: Combine lookup with conditional logic
A12: XLOOKUP + SUMIF | B12: =SUMIF('09_Pivot_Tables'!C6:C25,XLOOKUP("E001",'10_XLOOKUP_Advanced'!A6:A15,'10_XLOOKUP_Advanced'!B6:B15),'09_Pivot_Tables'!I6:I25) | C12: Sum orders for a specific sales rep found by ID
A13: Nested SUMIFS | B13: =SUMIFS(I6:I25,C6:C25,"Aarav Shah",D6:D25,"North") | C13: Total revenue for a specific person in a specific region
A14: XLOOKUP + CONCATENATE | B14: =XLOOKUP("E006",A6:A15,B6:B15)&" | "&XLOOKUP("E006",A6:A15,C6:C15)&" | "&TEXT(XLOOKUP("E006",A6:A15,E6:E15),"₹#,##0") | C14: Build an employee card string from lookup results
A15: Dynamic Summary Row | B15: =SUMPRODUCT((D6:D25="North")*(E6:E25="Electronics")*I6:I25) | C15: Sum with multiple conditions (alternative to SUMIFS)
A16: Running Total | B16: =SUM($I$6:I6) | C16: Cumulative revenue — copy down to see running total
A17: Year-over-Year | B17: =IFERROR((CurrentYear-PriorYear)/PriorYear,"N/A") | C17: Growth calculation with error handling
A19: REAL-WORLD USE CASES — Sales, HR, Stock Movement
A20: Sales Analytics | E20: Employee Performance | I20: Inventory / Stock
A21: ✓ XLOOKUP employee ID → get name/region for commission report | E21: ✓ DATEDIF: tenure calculation for appraisal eligibility | I21: ✓ SUMIF: total stock by warehouse or category
A22: ✓ SUMIFS: revenue by region AND product category AND month | E22: ✓ IFS: grade employees A+/A/B+/B/C based on KPIs | I22: ✓ XLOOKUP: find product details by SKU code
A23: ✓ Pivot: monthly trend → PivotChart for dashboard | E23: ✓ XLOOKUP: cross-reference HR records with Payroll data | I23: ✓ Conditional Formatting: flag low stock (< reorder level)
A24: ✓ Conditional Formatting: highlight reps above target in green | E24: ✓ NETWORKDAYS: calculate working days in review period | I24: ✓ Pivot: stock movement by month — group dates
A27: ✏️ EXERCISE — Advanced Integration — Combine all tools learned
A28: Q1: Build a Sales Rep scorecard: given an Emp ID, show Name, Region, Total Revenue, Avg Order, Order Count
A29: Q2: Create a cross-sheet formula that pulls an employee's rating from Sheet 10 and assigns a bonus %
A30: Q3: Build a running total column on the Pivot source data (Sheet 9) using SUM with locked start
A31: Q4: Create a 2-way summary: SUMIFS for each Region+Category combination (same as pivot but with formulas)
A32: Q5: Use XLOOKUP nested in a conditional: if rating='A+', lookup their project from Sheet 4 else show 'N/A'
A33: Q6: Build a dynamic dashboard: 3 KPI cards, 1 region chart, 1 category chart, linked to Pivot source
A34: Q7: Write a formula to find the Top 3 sales reps by revenue using LARGE + INDEX + MATCH
A35: Q8: Create a stock alert system: XLOOKUP product → if stock < reorder level → 'ORDER NOW' else 'OK'
A36: 💡 Professional analysts combine Pivot Tables (for exploration) with XLOOKUP+SUMIFS (for dynamic reports). Both tools are essential.
