Workbook

Sheet 📋 INDEX
B2: 🛒 Excel Data Analytics — Complete YouTube Tutorial Workbook
B3: E-Commerce Sales Data | Data Cleaning + Validation + Visualization + Dashboard · Telugu YouTube Tutorial
B5: Sheet | C5: Topic | D5: What's Inside
B6: Raw_Data | C6: 📊 Raw Data | D6: 500-row messy e-commerce dataset with 22 columns & all data issues
B7: Data_Cleaning_Steps | C7: 🧹 Cleaning Steps | D7: Step-by-step cleaning guide with formulas, before/after, exercises
B8: Clean_Data | C8: ✅ Clean Data | D8: Fully cleaned and standardized dataset ready for analysis
B9: Data_Validation | C9: ✔️ Data Validation | D9: Validation rules, drop-downs, custom formulas & practice form
B10: Lists | C10: 📋 Reference Lists | D10: Named range reference lists for all dropdown validations
B11: Chart_Data | C11: 📈 Chart Data | D11: Pre-summarized tables for all 5 charts (Region/Monthly/Category/etc.)
B12: Visualization_Guide | C12: 🎨 Visualization Guide | D12: Chart selection guide, step-by-step chart creation & common mistakes
B13: Dashboard | C13: 📊 Dashboard | D13: Interactive KPI dashboard with all business metrics for 2024
B14: Assignment | C14: 🎯 Assignment | D14: 100-mark student assignment with messy dataset to practice on
B16: 💡 How to Use: Start with Raw_Data sheet. Follow the Data_Cleaning_Steps guide. Practice validation in Data_Validation sheet. Build charts from Chart_Data. Replicate the Dashboard. Complete the Assignment!

Sheet Dumy_data
A1: Order_ID | B1: Order_Date | C1: Customer_Name | D1: Customer_ID | E1: Email | F1: Phone | G1: City | H1: State | I1: Region | J1: Product_ID | K1: Product_Name | L1: Category | M1: Sub_Category | N1: Brand | O1: Quantity | P1: Unit_Price | Q1: Discount_% | R1: GST_% | S1: Total_Amount | T1: Payment_Mode | U1: Order_Status | V1: Return_Flag
A2: ORD-1001 | B2: 2024-05-30 | C2: =IF(ISBLANK(Raw_Data!C2),"unknown",PROPER(TRIM(CLEAN(Raw_Data!C2)))) -> Arjun Mehta
A3: ORD-1002 | B3: 29-Jun-2024 | C3: =IF(ISBLANK(Raw_Data!C3),"unknown",PROPER(TRIM(CLEAN(Raw_Data!C3)))) -> Preethi S
A4: ORD-1003 | B4: 2024-06-24 | C4: =IF(ISBLANK(Raw_Data!C4),"unknown",PROPER(TRIM(CLEAN(Raw_Data!C4)))) -> Rekha Pandey
A5: ORD-1004 | B5: 24-Jan-2024 | C5: =IF(ISBLANK(Raw_Data!C5),"unknown",PROPER(TRIM(CLEAN(Raw_Data!C5)))) -> Geetha Rao
A6: ORD-1005 | B6: 09-May-2024 | C6: =IF(ISBLANK(Raw_Data!C6),"unknown",PROPER(TRIM(CLEAN(Raw_Data!C6)))) -> Dinesh K
A7: ORD-1006 | B7: 02/02/2024 | C7: =IF(ISBLANK(Raw_Data!C7),"unknown",PROPER(TRIM(CLEAN(Raw_Data!C7)))) -> Suresh Kumar
A8: ORD-1007 | B8: 28-Feb-2024 | C8: =IF(ISBLANK(Raw_Data!C8),"unknown",PROPER(TRIM(CLEAN(Raw_Data!C8)))) -> Swati Gupta
A9: ORD-1008 | B9: 2024-04-13 | C9: =IF(ISBLANK(Raw_Data!C9),"unknown",PROPER(TRIM(CLEAN(Raw_Data!C9)))) -> Nisha Patel
A10: ORD-1009 | B10: 12-Apr-2024 | C10: =IF(ISBLANK(Raw_Data!C10),"unknown",PROPER(TRIM(CLEAN(Raw_Data!C10)))) -> Kavya Rao
A11: ORD-1010 | B11: 10-May-2024 | C11: =IF(ISBLANK(Raw_Data!C11),"unknown",PROPER(TRIM(CLEAN(Raw_Data!C11)))) -> Rashmi Verma
A12: ORD-1011 | B12: 19-Jan-2024 | C12: =IF(ISBLANK(Raw_Data!C12),"unknown",PROPER(TRIM(CLEAN(Raw_Data!C12)))) -> Geetha Rao
A13: ORD-1012 | B13: 30-Jan-2024 | C13: =IF(ISBLANK(Raw_Data!C13),"unknown",PROPER(TRIM(CLEAN(Raw_Data!C13)))) -> Arun Sharma
... A481: ORD-1480 | B481: Mar-19-2024 | C481: =IF(ISBLANK(Raw_Data!C481),"unknown",PROPER(TRIM(CLEAN(Raw_Data!C481)))) -> Arun Sharma

Sheet Raw_Data
A1: Order_ID | B1: Order_Date | C1: Customer_Name | D1: Customer_ID | E1: Email | F1: Phone | G1: City | H1: State | I1: Region | J1: Product_ID | K1: Product_Name | L1: Category | M1: Sub_Category | N1: Brand | O1: Quantity | P1: Unit_Price | Q1: Discount_% | R1: GST_% | S1: Total_Amount | T1: Payment_Mode | U1: Order_Status | V1: Return_Flag
A2: ORD-1001 | B2: 2024-05-30 | C2: arjun mehta | D2: CUST-001 | E2: arjunmeh@gmail.com | F2: 7815115025 | G2: Hyderabad | H2: Telangana | I2: South | J2: PROD-108 | K2: Nescafe Classic 200g | L2: Grocery | M2: Beverage | N2: Nestlé | O2: 2 | P2: 450 | Q2: 0 | R2: 5 | S2: 945 | T2: CASH | U2: Cancelled | V2: 0
A3: ORD-1002 | B3: 29-Jun-2024 | C3: Preethi S | D3: CUST-002 | E3: @gmail | F3: 9673561638 | G3: Surat | H3: Gujarat | I3: West | J3: PROD-125 | K3: Tanishq Gold Ring | L3: Jewellery | M3: Gold | N3: Tanishq | O3: 10 | P3: 25000 | Q3: 20 | R3: 3 | S3: 206000 | T3: upi | U3: returned | V3: NO
A4: ORD-1003 | B4: 2024-06-24 | C4: rekha pandey | D4: CUST-003 | E4: rekhapan@gmail.com | F4: 769357567 | G4: Bangalore | H4: Karnataka | I4: South | J4: PROD-115 | K4: OnePlus Nord CE 3 | L4: Electronics | M4: Mobile | N4: OnePlus | O4: 5 | P4: 28000 | Q4: 10 | R4: 18 | S4: 148680 | T4: Net Banking | U4: shipped | V4: NO
A5: ORD-1004 | B5: 24-Jan-2024 | C5: Geetha Rao | D5: CUST-004 | E5: geethara@yahoo.com | F5: 7813163240 | G5: Surat | H5: Gujarat | I5: West | J5: PROD-119 | K5: Fastrack Reflex Beat | L5: Fashion | M5: Accessories | N5: Fastrack | O5: 8 | P5: 3500 | Q5: 20 | R5: 18 | S5: 26432 | T5: Debit Card | U5: shipped | V5: 0
A6: ORD-1005 | B6: 09-May-2024 | C6: DINESH K | D6: CUST-005 | E6: dineshk@outlook.com | F6: 6854316681 | G6: Delhi | H6: Delhi | I6: North | J6: PROD-120 | K6: Samsung Galaxy M14 | L6: Electronics | M6: Mobile | N6: Samsung | O6: 1 | P6: 14000 | Q6: 15 | R6: 18 | S6: 14042 | T6: EMI | U6: shipped | V6: no
A7: ORD-1006 | B7: 02/02/2024 | C7: Suresh Kumar | D7: CUST-006 | E7: sureshku@rediffmail.com | F7: 8605301030 | G7: Kochi | H7: Kerala | I7: South | J7: PROD-118 | K7: Voltas 1.5T Desert Cooler | L7: Home | M7: Appliance | N7: Voltas | O7: -3 | P7: 12000 | Q7: 0 | R7: 18 | S7: -42480 | T7: Debit card | U7: Shipped | V7: 1
A8: ORD-1007 | B8: 28-Feb-2024 | C8: swati gupta | D8: CUST-007 | E8: swatigup@outlook.com | F8: 8873237671 | G8: Pune | H8: Maharashtra | I8: West | J8: PROD-125 | K8: Tanishq Gold Ring | L8: Jewellery | M8: Gold | N8: Tanishq | O8: 6 | P8: 25000 | Q8: 136 | R8: 3 | T8: Credit Card | U8: CANCELLED | V8: No
A9: ORD-1008 | B9: 2024-04-13 | C9: nisha patel | D9: CUST-008 | E9: nishapat@gmail.com | F9: 7926780541 | G9: Pune | H9: Maharashtra | I9: West | J9: PROD-124 | K9: Realme Buds Air 3 | L9: Electronics | M9: Audio | N9: Realme | O9: 7 | P9: 2800 | Q9: 25 | R9: 18 | S9: 17346 | T9: Net Banking | U9: Shipped | V9: No
A10: ORD-1009 | B10: 12-Apr-2024 | C10: Kavya Rao | D10: CUST-009 | E10: kavyarao@gmail.com | F10: 9367557574 | G10: Bengaluru | H10: Karnataka | I10: South | J10: PROD-115 | K10: OnePlus Nord CE 3 | L10: Electronics | M10: Mobile | N10: OnePlus | O10: 9 | P10: ₹28,000 | Q10: 5 | R10: 18 | S10: 282492 | T10: Debit card | U10: Dlvrd | V10: NO
A11: ORD-1010 | B11: 10-May-2024 | C11: RASHMI VERMA | D11: CUST-010 | E11: rashmive@gmail.com | F11: 7010193046 | G11: Jaipur | H11: Rajasthan | I11: North | J11: PROD-124 | K11: Realme Buds Air 3 | L11: Electronics | M11: Audio | N11: Realme | O11: 5 | P11: 2800 | Q11: 15 | R11: 18 | S11: 14042 | T11: credit card | U11: Returned | V11: No
A12: ORD-1011 | B12: 19-Jan-2024 | C12: Geetha Rao | D12: CUST-011 | E12: geethara@rediffmail.com | F12: 6915490795 | G12: Bangalore | H12: Karnataka | I12: South | J12: PROD-119 | K12: Fastrack Reflex Beat | L12: Fashion | M12: Accessories | N12: Fastrack | O12: 10 | P12: 3500 | Q12: 15 | R12: 18 | S12: 35105 | T12: EMI | U12: Dlvrd | V12: N
A13: ORD-1012 | B13: 30-Jan-2024 | C13: ARUN SHARMA | D13: CUST-012 | E13: arunshar@yahoo.com | F13: 9082120871 | G13: Surat | H13: Gujarat | I13: West | J13: PROD-112 | K13: Britannia Good Day | L13: Grocery | M13: Snacks | N13: Britannia | O13: 9 | P13: 50 | Q13: 0 | R13: 5 | S13: 472 | T13: Credit Card | U13: Returned | V13: YES
A14: ORD-1013 | B14: 20/01/2024 | C14: Preethi S | D14: CUST-013 | E14: preethis@outlook.com | F14: 6547374338 | G14: Pune | H14: Maharashtra | I14: West | J14: PROD-109 | K14: HP Pavilion Laptop | L14: Electronics | M14: Computer | N14: HP | O14: 7 | P14: 55000 | Q14: 12 | R14: 18 | S14: 399784 | T14: credit card | U14: Delivered | V14: Yes
A15: ORD-1014 | B15: Mar-26-2024 | C15: AMIT SINGH | D15: CUST-014 | E15: amitsing@yahoo.com | F15: 6464267175 | G15: Jaipur | H15: Rajasthan | I15: North | J15: PROD-102 | K15: iPhone 14 Pro | L15: Electronics | M15: Mobile | N15: Apple | O15: 9 | P15: 89000 | Q15: 10 | R15: 18 | S15: 850662 | T15: CASH | U15: Delivered | V15: no
A16: ORD-1015 | B16: 25-Mar-2024 | C16: suresh babu | D16: CUST-015 | E16: sureshba@outlook.com | F16: 7140169349 | G16: Mumbai | H16: Maharashtra | I16: West | J16: PROD-108 | K16: Nescafe Classic 200g | L16: Grocery | M16: Beverage | N16: Nestlé | O16: 4 | P16: 450 | Q16: 5 | R16: 5 | S16: 1796 | T16: CASH | U16: CANCELLED | V16: 1
A17: ORD-1016 | B17: 18-Jun-2024 | C17: AMIT SINGH | D17: CUST-016 | E17: amitsing@outlook.com | F17: 7400944900 | G17: Bangalore | H17: Karnataka | I17: South | J17: PROD-112 | K17: Britannia Good Day | L17: Grocery | M17: Snacks | N17: Britannia | O17: 7 | P17: 50 | Q17: 10 | R17: 5 | S17: 331 | T17: upi | U17: returned | V17: N
A18: ORD-1017 | B18: 21/06/2024 | C18: Geetha Rao | D18: CUST-017 | E18: geethara@yahoo.com | F18: 8851230518 | G18: Jaipur | H18: Rajasthan | I18: North | J18: PROD-107 | K18: Levi's 511 Jeans | L18: Fashion | M18: Clothing | N18: Levi's | O18: 10 | P18: 2500 | Q18: 10 | R18: 5 | S18: 23625 | T18: Debit card | U18: Dlvrd | V18: 0
A19: ORD-1018 | B19: 03/03/2024 | C19: padma lakshmi | D19: CUST-018 | E19: padmalak@gmail.com | F19: 9803044105 | G19: Lucknow | H19: Uttar Pradesh | I19: North | J19: PROD-125 | K19: Tanishq Gold Ring | L19: Jewellery | M19: Gold | N19: Tanishq | O19: 1 | P19: 25000 | Q19: 20 | R19: 3 | S19: 20600 | T19: CASH | U19: Dlvrd | V19: Y
A20: ORD-1019 | B20: 24/04/2024 | C20: DEEPA KRISHNAN | D20: CUST-019 | E20: deepakri@hotmail.com | F20: 9607183629 | G20: Bengaluru | H20: Karnataka | I20: South | J20: PROD-123 | K20: Syska LED Bulb Pack | L20: Home | M20: Lighting | N20: Syska | O20: 8 | P20: 299 | Q20: 15 | R20: 18 | S20: 2399 | T20: credit card | U20: DELIVERED | V20: 1
A21: ORD-1020 | B21: 16/01/2024 | C21: Anita Verma | D21: CUST-020 | E21: anitaver@hotmail.com | F21: 8987248494 | G21: delhi | H21: Delhi | I21: North | J21: PROD-108 | K21: Nescafe Classic 200g | L21: Grocery | M21: Beverage | N21: Nestlé | O21: 6 | P21: 450 | Q21: 8 | R21: 5 | S21: 2608 | T21: credit card | U21: Dlvrd | V21: Y
A22: ORD-1021 | B22: 29/04/2024 | C22: priya sharma | D22: CUST-021 | E22: priyasha@rediffmail.com | G22: bangalor | H22: Karnataka | I22: South | J22: PROD-101 | K22: Samsung TV 43" | L22: Electronics | M22: Television | N22: Samsung | O22: 7 | P22: 35000 | Q22: 25 | R22: 18 | S22: 217734 | T22: Net Banking | U22: DELIVERED | V22: no
A23: ORD-1022 | B23: 18-May-2024 | C23: Geetha Rao | D23: CUST-022 | E23: geethara@outlook.com | F23: 8799264931 | G23: bangalor | H23: Karnataka | I23: South | J23: PROD-101 | K23: Samsung TV 43" | L23: Electronics | M23: Television | N23: Samsung | O23: 5 | P23: 35000 | Q23: 20 | R23: 18 | S23: 165200 | T23: Credit Card | U23: Dlvrd | V23: No
A24: ORD-1023 | B24: 28-May-2024 | C24: AMIT SINGH | D24: CUST-023 | E24: amitsing@rediffmail.com | F24: 7703617827 | G24: Hyderabad | H24: Telangana | I24: South | J24: PROD-107 | K24: Levi's 511 Jeans | L24: Fashion | M24: Clothing | N24: Levi's | O24: 2 | P24: 2500 | Q24: 8 | R24: 5 | S24: 4830 | T24: Debit Card | U24: Pending | V24: Yes
A25: ORD-1024 | B25: Apr-02-2024 | C25: Divya Nair | D25: CUST-024 | E25: divyanai@hotmail.com | F25: 8793693337 | G25: Delhi | H25: Delhi | I25: North | J25: PROD-121 | K25: Amul Butter 500g | L25: Grocery | M25: Dairy | N25: Amul | O25: 2 | P25: 280 | Q25: 15 | R25: 5 | S25: 565 | T25: Debit card | U25: Shipped | V25: Y
A26: ORD-1025 | B26: 24/03/2024 | C26: Anita Verma | D26: CUST-025 | E26: anitaver@outlook.com | F26: 9780945510 | G26: kolkata | H26: West Bengal | I26: East | J26: PROD-118 | K26: Voltas 1.5T Desert Cooler | L26: Home | M26: Appliance | N26: Voltas | O26: 6 | P26: 12000 | Q26: 10 | R26: 18 | S26: 76464 | T26: upi | U26: Delivered | V26: 0
A27: ORD-1026 | B27: 2024-05-01 | C27: DINESH K | D27: CUST-026 | E27: dineshk@rediffmail.com | F27: 7163577186 | G27: Surat | H27: Gujarat | I27: West | J27: PROD-117 | K27: Parle-G Family Pack | L27: Grocery | M27: Snacks | N27: Parle | O27: 4 | P27: 40 | Q27: 5 | R27: 5 | S27: 160 | T27: Net Banking | U27: returned | V27: N
A28: ORD-1027 | B28: 04/01/2024 | C28: SITA DEVI | D28: CUST-027 | E28: sitadevi@gmail.com | F28: 6542366274 | G28: Surat | H28: Gujarat | I28: West | J28: PROD-124 | K28: Realme Buds Air 3 | L28: Electronics | M28: Audio | N28: Realme | O28: 3 | P28: 2800 | Q28: 12 | R28: 18 | S28: 8723 | T28: upi | U28: Returned | V28: YES
A29: ORD-1028 | B29: 04-Mar-2024 | C29: nisha patel | D29: CUST-028 | E29: nishapat@hotmail.com | F29: 6969318858 | G29: Bangalore | H29: Karnataka | I29: South | J29: PROD-119 | K29: Fastrack Reflex Beat | L29: Fashion | M29: Accessories | N29: Fastrack | O29: 5 | P29: 3500 | Q29: 5 | R29: 18 | S29: 19618 | T29: Cash on Delivery | U29: Pending | V29: Yes
A30: ORD-1029 | B30: Jan-01-2024 | C30: deepika rao | D30: CUST-029 | E30: deepikar@rediffmail.com | F30: 754675132 | G30: Visakhapatnam | H30: Andhra Pradesh | I30: South | J30: PROD-115 | K30: OnePlus Nord CE 3 | L30: Electronics | M30: Mobile | N30: OnePlus | O30: 1 | P30: 28000 | Q30: 10 | R30: 18 | S30: 29736 | T30: credit card | U30: Shipped | V30: no
A31: ORD-1030 | B31: Feb-01-2024 | C31: Rahul Gupta | D31: CUST-030 | E31: rahulgup@hotmail.com | F31: 8120834317 | G31: Hydrabad | H31: Telangana | I31: South | J31: PROD-108 | K31: Nescafe Classic 200g | L31: Grocery | M31: Beverage | N31: Nestlé | O31: 4 | P31: 450 | Q31: 8 | R31: 5 | S31: 1739 | T31: Cash on Delivery | U31: Pending | V31: 0
A32: ORD-1031 | B32: May-29-2024 | D32: CUST-031 | E32: user@hotmail.com | F32: 7753841726 | G32: Delhi | H32: Delhi | I32: North | J32: PROD-114 | K32: Philips Mixer Grinder | L32: Home | M32: Kitchen | N32: Philips | O32: 10 | P32: 3200 | Q32: 0 | R32: 18 | S32: 37760 | T32: Debit card | U32: Pending | V32: no
A33: ORD-1032 | B33: 2024-02-18 | C33: Preethi S | D33: CUST-032 | E33: preethis@hotmail.com | F33: 6874275988 | G33: Lucknow | H33: Uttar Pradesh | I33: North | J33: PROD-106 | K33: LG Double Door Refrigerator | L33: Home | M33: Appliance | N33: LG | O33: 9 | P33: 42000 | Q33: 20 | R33: 18 | S33: 643743 | T33: Debit card | U33: DELIVERED | V33: No
A34: ORD-1033 | B34: 2024-05-07 | C34: Anita Verma | D34: CUST-033 | E34: anitaver@outlook.com | F34: 8028168523 | G34: CHENNAI | H34: Tamil Nadu | I34: South | J34: PROD-110 | K34: Banarasi Silk Saree | L34: Fashion | M34: Traditional | N34: Fab India | O34: 10 | P34: ₹3,500 | Q34: 20 | R34: 5 | S34: 29400 | T34: Debit card | U34: Shipped | V34: no
A35: ORD-1034 | B35: Feb-08-2024 | C35: Vijay Patel | D35: CUST-034 | E35: vijaypat@outlook.com | F35: 7620104855 | G35: Hydrabad | H35: Telangana | I35: South | J35: PROD-113 | K35: Titan Raga Watch | L35: Fashion | M35: Accessories | N35: Titan | O35: 2 | P35: 8500 | Q35: 12 | R35: 18 | S35: 17653 | T35: Cash on Delivery | U35: returned | V35: 0
A36: ORD-1035 | B36: 22-Apr-2024 | C36: RASHMI VERMA | D36: CUST-035 | E36: rashmive@hotmail.com | G36: Lucknow | H36: Uttar Pradesh | I36: North | J36: PROD-123 | K36: Syska LED Bulb Pack | L36: Home | M36: Lighting | N36: Syska | O36: 6 | P36: 299 | Q36: 8 | R36: 18 | S36: 1948 | T36: Cash on Delivery | U36: deliverd | V36: Yes
A37: ORD-1036 | B37: 07-Jun-2024 | C37: Suresh Kumar | D37: CUST-036 | E37: sureshku@outlook.com | F37: 7863893256 | G37: Bengaluru | H37: Karnataka | I37: South | J37: PROD-105 | K37: Boat Airdopes 141 | L37: Electronics | M37: Audio | N37: Boat | O37: 7 | P37: 1500 | Q37: 20 | R37: 18 | S37: 9912 | T37: Debit card | U37: shipped | V37: No
A38: ORD-1037 | B38: 07/05/2024 | C38: DEEPA KRISHNAN | D38: CUST-037 | E38: deepakri@outlook.com | F38: 9860782736 | G38: Bangalore | H38: Karnataka | I38: South | J38: PROD-123 | L38: Home | M38: Lighting | N38: Syska | O38: 6 | P38: 299 | Q38: 8 | R38: 18 | S38: 1948 | T38: Cash on Delivery | U38: CANCELLED | V38: NO
A39: ORD-1020 | B39: 16/01/2024 | C39: Anita Verma | D39: CUST-020 | E39: anitaver@hotmail.com | F39: 8987248494 | G39: delhi | H39: Delhi | I39: North | J39: PROD-108 | K39: Nescafe Classic 200g | L39: Grocery | M39: Beverage | N39: Nestlé | O39: 6 | P39: 450 | Q39: 8 | R39: 5 | S39: 2608 | T39: credit card | U39: Dlvrd | V39: Y
A40: ORD-1016 | B40: 18-Jun-2024 | C40: AMIT SINGH | D40: CUST-016 | E40: amitsing@outlook.com | F40: 7400944900 | G40: Bangalore | H40: Karnataka | I40: South | J40: PROD-112 | K40: Britannia Good Day | L40: Grocery | M40: Snacks | N40: Britannia | O40: 7 | P40: 50 | Q40: 10 | R40: 5 | S40: 331 | T40: upi | U40: returned | V40: N
...

Sheet Data_Cleaning_Steps
A1: 🧹 DATA CLEANING STEPS — Step-by-Step Guide with Formulas, Before/After Examples & Mini Exercises
A2: STEP 01 — REMOVE DUPLICATES
A3: Telugu: Data lo same Order_ID rendu sarlu vastundi. Idi totals ni wrongly double chestundi. COUNTIF formula use chesi flag cheyyi, tarvata Data → Remove Duplicates use cheyyandi.
A4: Step | B4: Action | C4: Formula / Method | D4: Expected Result
A5: 1 | B5: Add helper column 'Dup_Flag' in column W | C5: =IF(COUNTIF($A2:$A$3,A3)>1,"DUPLICATE","UNIQUE") -> UNIQUE | D5: Shows DUPLICATE for repeated Order_IDs
A6: 2 | B6: Filter column W for 'DUPLICATE' | C6: Data → Filter → Filter by 'DUPLICATE' | D6: All duplicate rows visible
A7: 3 | B7: Review and delete duplicates | C7: Select rows → Right click → Delete Row | D7: ~20 duplicate rows removed
A8: 4 | B8: Alternative: Use Excel built-in | C8: Data tab → Remove Duplicates → Select 'Order_ID' → OK | D8: Excel removes dupes automatically
A9: 5 | B9: Verify count after removal | C9: {=COUNTA(A3:A502)-SUMPRODUCT((COUNTIF(A3:A502,A3:A502)>1)/COUNTIF(A3:A502,A3:A502))} -> #DIV/0! | D9: Should equal 0 duplicates remaining
A10: ✏️ MINI EXERCISE: Open Raw_Data sheet. Add column W named 'Dup_Flag'. Write the formula. Count how many duplicates exist. Record the number.
A12: STEP 02 — TRIM & CLEAN — Remove Extra Spaces & Hidden Characters
A13: Function | B13: Syntax | C13: Before | D13: After | E13: Apply To
A14: TRIM | B14: =TRIM(text) -> #NAME? | C14: Sneha Reddy | D14: Sneha Reddy | E14: Customer_Name, City, Product_Name
A15: CLEAN | B15: =CLEAN(text) -> #NAME? | C15: Ravi Kumar | D15: Ravi Kumar | E15: Data imported from other systems
A16: TRIM+CLEAN | B16: =TRIM(CLEAN(C3)) | C16: AMIT SINGH | D16: AMIT SINGH | E16: Use both together always
A17: With PROPER | B17: =PROPER(TRIM(CLEAN(C3))) | C17: amit singh | D17: Amit Singh | E17: Best practice for names
A18: ✏️ MINI EXERCISE: Create Clean_Data sheet. Copy headers. In C3 write =PROPER(TRIM(CLEAN(Raw_Data!C3))). Copy down all 500 rows. Count how many changed.
A20: STEP 03 — HANDLE MISSING VALUES (BLANKS)
A21: Column | B21: Detection Formula | C21: Fill Strategy | D21: Formula
A22: Customer_Name | B22: =COUNTBLANK(C3:C502) -> 451 | C22: Fill with 'Unknown' | D22: =IF(ISBLANK(Raw_Data!C2),"Unknown",PROPER(TRIM(Raw_Data!C2))) -> Arjun Mehta
A23: Customer_ID | B23: =COUNTBLANK(D3:D502) -> 452 | C23: Flag as 'MISSING' | D23: =IF(ISBLANK(Raw_Data!D2),"MISSING",Raw_Data!D2) -> CUST-001
A24: Phone | B24: =COUNTBLANK(G3:G502) -> 500 | C24: Fill 'Not Provided' | D24: =IF(OR(ISBLANK(Raw_Data!G2),Raw_Data!G2=""),"Not Provided",Raw_Data!G2) -> Hyderabad
A25: Unit_Price | B25: =COUNTBLANK(Q3:Q502) -> 500 | C25: Fill 0 & Flag | D25: =IF(ISBLANK(Raw_Data!Q2),0,Raw_Data!Q2) -> 0
A26: Product_Name | B26: =COUNTBLANK(L3:L502) -> 500 | C26: Flag 'Check Required' | D26: =IF(ISBLANK(Raw_Data!L2),"Check Required",PROPER(TRIM(Raw_Data!L2))) -> Grocery
A27: ✏️ MINI EXERCISE: Use COUNTBLANK() to create a data quality summary — count blanks in each of the 22 columns and list them in a table.
A29: STEP 04 — FIX DATE FORMATS — Standardize to DD-MMM-YYYY
A30: Issue | B30: Example Input | C30: Problem | D30: Fix Formula | E30: Clean Output
A31: Mixed separators | B31: 15/01/2024 | C31: DD/MM or MM/DD ambiguous | D31: =DATEVALUE(TEXT(B3,"DD-MM-YYYY")) -> #VALUE! | E31: 15-Jan-2024
A32: ISO format | B32: 2024-01-15 | C32: Text not recognized | D32: =DATE(LEFT(B3,4),MID(B3,6,2),RIGHT(B3,2)) -> #VALUE! | E32: 15-Jan-2024
A33: US format | B33: Jan-17-2024 | C33: Month-Day-Year order | D33: =DATEVALUE(B3) -> #VALUE! | E33: 17-Jan-2024
A34: Extract Day | B34: 15-Jan-2024 | C34: Need Day number | D34: =DAY(B3) -> 0 | E34: 15
A35: Extract Month Name | B35: 15-Jan-2024 | C35: Need Month name | D35: =TEXT(B3,"MMMM") -> January | E35: January
A36: Extract Year | B36: 15-Jan-2024 | C36: Need Year | D36: =YEAR(B3) -> 1900 | E36: 2024
A37: Day of Week | B37: 15-Jan-2024 | C37: Need weekday | D37: =TEXT(B3,"DDDD") -> Saturday | E37: Monday
A38: ✏️ MINI EXERCISE: Add 3 new columns to Clean_Data: Order_Day, Order_Month, Order_Year using DAY(), MONTH(), YEAR() functions on the cleaned date column.
A40: STEP 05 — STANDARDIZE CATEGORIES & TEXT FIELDS
A41: Column | B41: Issue | C41: Before | D41: Formula | E41: After
A42: Category | B42: Wrong casing/typo | C42: Electronicss | D42: =IF(LOWER(TRIM(L3))="electronics","Electronics",IF(LOWER(TRIM(L3))="fashion","Fashion",IF(LOWER(TRIM(L3))="grocery","Grocery",IF(LOWER(TRIM(L3))="home","Home","Check Required")))) -> Check Required | E42: Electronics
A43: Order_Status | B43: Inconsistent | C43: deliverd | D43: =IF(LOWER(TRIM(U3))="delivered","Delivered",IF(LOWER(TRIM(U3))="shipped","Shipped",IF(LOWER(TRIM(U3))="returned","Returned",IF(LOWER(TRIM(U3))="cancelled","Cancelled","Pending")))) -> Pending | E43: Delivered
A44: Region | B44: Typos/wrong values | C44: Soth | D44: =IFERROR(_xludf.SWITCH(LOWER(TRIM(I3)),"north","North","south","South","east","East","west","West"),"Check Required") -> Check Required | E44: South
...

Sheet Clean_Data
A1: ✅ CLEAN DATA — Processed & Standardized Dataset | Ready for Analysis
A2: Order_ID | B2: Order_Date | C2: Customer_Name | D2: Customer_ID | E2: Email | F2: Phone | G2: City | H2: State | I2: Region | J2: Product_ID | K2: Product_Name | L2: Category | M2: Sub_Category | N2: Brand | O2: Quantity | P2: Unit_Price | Q2: Discount_% | R2: GST_% | S2: Total_Amount | T2: Payment_Mode | U2: Order_Status | V2: Return_Flag
A3: ORD-1001 | B3: 2024-04-07 | C3: Arjun Mehta | D3: CUST-001 | E3: arjunmeh@gmail.com | F3: 7815115025 | G3: Hyderabad | H3: Telangana | I3: South | J3: PROD-108 | K3: Nescafe Classic 200G | L3: Grocery | M3: Beverage | N3: Nestlé | O3: 2 | P3: 450 | Q3: 0 | R3: 5 | S3: 945 | T3: Cash | U3: Cancelled | V3: No
A4: ORD-1002 | B4: 2024-04-02 | C4: Preethi S | D4: CUST-002 | E4: preethi@gmail.com | F4: 9673561638 | G4: Surat | H4: Gujarat | I4: West | J4: PROD-125 | K4: Tanishq Gold Ring | L4: Jewellery | M4: Gold | N4: Tanishq | O4: 10 | P4: 25000 | Q4: 20 | R4: 3 | S4: 206000 | T4: UPI | U4: Returned | V4: No
A5: ORD-1003 | B5: 2024-03-02 | C5: Rekha Pandey | D5: CUST-003 | E5: rekhapan@gmail.com | F5: Not Provided | G5: Bangalore | H5: Karnataka | I5: South | J5: PROD-115 | K5: Oneplus Nord Ce 3 | L5: Electronics | M5: Mobile | N5: Oneplus | O5: 5 | P5: 28000 | Q5: 10 | R5: 18 | S5: 148680 | T5: Net Banking | U5: Shipped | V5: No
A6: ORD-1004 | B6: 2024-04-26 | C6: Geetha Rao | D6: CUST-004 | E6: geethara@yahoo.com | F6: 7813163240 | G6: Surat | H6: Gujarat | I6: West | J6: PROD-119 | K6: Fastrack Reflex Beat | L6: Fashion | M6: Accessories | N6: Fastrack | O6: 8 | P6: 3500 | Q6: 20 | R6: 18 | S6: 26432 | T6: Debit Card | U6: Shipped | V6: No
A7: ORD-1005 | B7: 2024-06-23 | C7: Dinesh K | D7: CUST-005 | E7: dineshk@outlook.com | F7: 6854316681 | G7: Delhi | H7: Delhi | I7: North | J7: PROD-120 | K7: Samsung Galaxy M14 | L7: Electronics | M7: Mobile | N7: Samsung | O7: 1 | P7: 14000 | Q7: 15 | R7: 18 | S7: 14042 | T7: EMI | U7: Shipped | V7: No
A8: ORD-1006 | B8: 2024-05-04 | C8: Suresh Kumar | D8: CUST-006 | E8: sureshku@rediffmail.com | F8: 8605301030 | G8: Kochi | H8: Kerala | I8: South | J8: PROD-118 | K8: Voltas 1.5T Desert Cooler | L8: Home | M8: Appliance | N8: Voltas | O8: 1 | P8: 12000 | Q8: 0 | R8: 18 | S8: 14160 | T8: Debit Card | U8: Shipped | V8: Yes
A9: ORD-1007 | B9: 2024-05-03 | C9: Swati Gupta | D9: CUST-007 | E9: swatigup@outlook.com | F9: 8873237671 | G9: Pune | H9: Maharashtra | I9: West | J9: PROD-125 | K9: Tanishq Gold Ring | L9: Jewellery | M9: Gold | N9: Tanishq | O9: 6 | P9: 25000 | Q9: 80 | R9: 3 | S9: 30900 | T9: Credit Card | U9: Cancelled | V9: No
A10: ORD-1008 | B10: 2024-06-21 | C10: Nisha Patel | D10: CUST-008 | E10: nishapat@gmail.com | F10: 7926780541 | G10: Pune | H10: Maharashtra | I10: West | J10: PROD-124 | K10: Realme Buds Air 3 | L10: Electronics | M10: Audio | N10: Realme | O10: 7 | P10: 2800 | Q10: 25 | R10: 18 | S10: 17346 | T10: Net Banking | U10: Shipped | V10: No
A11: ORD-1009 | B11: 2024-03-17 | C11: Kavya Rao | D11: CUST-009 | E11: kavyarao@gmail.com | F11: 9367557574 | G11: Bengaluru | H11: Karnataka | I11: South | J11: PROD-115 | K11: Oneplus Nord Ce 3 | L11: Electronics | M11: Mobile | N11: Oneplus | O11: 9 | P11: 28000 | Q11: 5 | R11: 18 | S11: 282492 | T11: Debit Card | U11: Delivered | V11: No
A12: ORD-1010 | B12: 2024-05-19 | C12: Rashmi Verma | D12: CUST-010 | E12: rashmive@gmail.com | F12: 7010193046 | G12: Jaipur | H12: Rajasthan | I12: North | J12: PROD-124 | K12: Realme Buds Air 3 | L12: Electronics | M12: Audio | N12: Realme | O12: 5 | P12: 2800 | Q12: 15 | R12: 18 | S12: 14042 | T12: Credit Card | U12: Returned | V12: No
A13: ORD-1011 | B13: 2024-06-18 | C13: Geetha Rao | D13: CUST-011 | E13: geethara@rediffmail.com | F13: 6915490795 | G13: Bangalore | H13: Karnataka | I13: South | J13: PROD-119 | K13: Fastrack Reflex Beat | L13: Fashion | M13: Accessories | N13: Fastrack | O13: 10 | P13: 3500 | Q13: 15 | R13: 18 | S13: 35105 | T13: EMI | U13: Delivered | V13: No
A14: ORD-1012 | B14: 2024-05-13 | C14: Arun Sharma | D14: CUST-012 | E14: arunshar@yahoo.com | F14: 9082120871 | G14: Surat | H14: Gujarat | I14: West | J14: PROD-112 | K14: Britannia Good Day | L14: Grocery | M14: Snacks | N14: Britannia | O14: 9 | P14: 50 | Q14: 0 | R14: 5 | S14: 472 | T14: Credit Card | U14: Returned | V14: Yes
... A482: ORD-1480 | B482: 2024-05-16 | C482: Sneha Reddy | D482: CUST-480 | E482: snehared@outlook.com | F482: Not Provided | G482: Kolkata | H482: West Bengal | I482: East | J482: PROD-124 | K482: Realme Buds Air 3 | L482: Electronics | M482: Audio | N482: Realme | O482: 3 | P482: 2800 | Q482: 8 | R482: 18 | S482: 9119 | T482: UPI | U482: Delivered | V482: No
A484: 💡 ✅ Clean Data: 480 rows after removing ~20 duplicates & fixing all data quality issues | Ready for Pivot Tables & Dashboard

Sheet Data_Validation
A1: ✅ DATA VALIDATION — Rules, Drop-downs & Custom Formulas
A2: 📌 Telugu: Data entry time lo wrong values enter avvakaundaniki Data Validation use chestham. Idi prevent chestundi errors before they happen!
A4: REFERENCE LISTS (Named Ranges for Validations)
A5: Valid Regions | B5: Valid Categories | C5: Valid Payment Modes | D5: Valid Order Status | E5: Valid Return Flag | F5: Valid States
A6: North | B6: Electronics | C6: UPI | D6: Delivered | E6: Yes | F6: Telangana
A7: South | B7: Fashion | C7: Credit Card | D7: Shipped | E7: No | F7: Maharashtra
A8: East | B8: Grocery | C8: Debit Card | D8: Returned | F8: Delhi
A9: West | B9: Home | C9: Cash | D9: Cancelled | F9: Karnataka
B10: Jewellery | C10: EMI | D10: Pending | F10: Tamil Nadu
C11: Net Banking | F11: Gujarat
F12: Rajasthan
F13: West Bengal
F14: Uttar Pradesh
F15: Kerala
F16: Andhra Pradesh
A18: VALIDATION RULES GUIDE — How to Apply Each Rule
A19: # | B19: Column | C19: Validation Type | D19: Settings | E19: Error Message | F19: Step-by-Step
A20: 1 | B20: Region (I) | C20: List | D20: Source: North,South,East,West | E20: Invalid! Select: North/South/East/West | F20: Data → Validation → Allow: List → Source: North,South,East,West
A21: 2 | B21: Category (L) | C21: List | D21: Source: =CategoryList (named range) | E21: Invalid Category! Use the dropdown. | F21: Create named range first, then Data → Validation → List → =CategoryList
A22: 3 | B22: Quantity (O) | C22: Whole Number | D22: Min: 1 | Max: 100 | E22: Quantity must be between 1 and 100 | F22: Data → Validation → Whole Number → Between 1 and 100
A23: 4 | B23: Discount_% (R) | C23: Decimal | D23: Min: 0 | Max: 80 | E23: Discount cannot exceed 80% | F23: Data → Validation → Decimal → Between 0 and 80
A24: 5 | B24: Unit_Price (Q) | C24: Decimal | D24: Min: 1 | Max: 500000 | E24: Price must be positive | F24: Data → Validation → Decimal → Greater than 0
A25: 6 | B25: Order_Date (B) | C25: Date | D25: End: =TODAY() | E25: Order date cannot be future | F25: Data → Validation → Date → Less than or equal to =TODAY()
A26: 7 | B26: Email (E) | C26: Custom Formula | D26: =AND(ISNUMBER(FIND("@",E3)),ISNUMBER(FIND(".",E3))) -> FALSE | E26: Invalid email format! Need @ and . | F26: Data → Validation → Custom → enter formula
A27: 8 | B27: Phone (F) | C27: Custom Formula | D27: =AND(LEN(F3)=10,ISNUMBER(VALUE(F3))) -> FALSE | E27: Phone must be exactly 10 digits | F27: Data → Validation → Custom → =AND(LEN(F3)=10,ISNUMBER(VALUE(F3)))
A28: 9 | B28: Return_Flag (V) | C28: List | D28: Source: Yes,No | E28: Select Yes or No only | F28: Data → Validation → List → Yes,No
A29: 10 | B29: Order_Status (U) | C29: List | D29: Source: =OrderStatusList | E29: Select valid status only | F29: Create named range, then apply list validation
A31: ✏️ PRACTICE SHEET — Enter data below. Validations are applied. Try entering invalid values!
A32: Order_ID | B32: Order_Date | C32: Customer_Name | D32: Region | E32: Category | F32: Quantity | G32: Unit_Price | H32: Discount_% | I32: Payment_Mode | J32: Order_Status
A33: ORD-XXXX | B33: 2024-06-15 | C33: Your Name Here | D33: South | E33: Electronics | F33: 2 | G33: 15000 | H33: 10 | I33: UPI | J33: Delivered
A34: ORD-YYYY | B34: 2024-07-20 | C34: Test User | D34: North | E34: Fashion | F34: 1 | G34: 3500 | H34: 15 | I34: Credit Card | J34: Shipped

Sheet Lists
A1: 📋 REFERENCE LISTS — Named Ranges for Data Validation Dropdowns
A2: Region | B2: Category | C2: Payment_Mode | D2: Order_Status | E2: Return_Flag | F2: Gender | G2: Sub_Category | H2: Brand
A3: North | B3: Electronics | C3: UPI | D3: Delivered | E3: Yes | F3: Male | G3: Mobile | H3: Samsung
A4: South | B4: Fashion | C4: Credit Card | D4: Shipped | E4: No | F4: Female | G4: Television | H4: Apple
A5: East | B5: Grocery | C5: Debit Card | D5: Returned | F5: Other | G5: Laptop | H5: Nike
A6: West | B6: Home | C6: Cash | D6: Cancelled | G6: Audio | H6: Prestige
B7: Jewellery | C7: EMI | D7: Pending | G7: Computer | H7: Boat
C8: Net Banking | G8: Footwear | H8: LG
G9: Clothing | H9: Levi's
G10: Accessories | H10: Nestlé
G11: Traditional | H11: HP
G12: Kitchen | H12: Fab India
G13: Appliance | H13: Whirlpool
G14: Beverage | H14: Britannia
G15: Snacks | H15: Titan
G16: Dairy | H16: Philips
G17: Lighting | H17: OnePlus
G18: Travel | H18: Adidas
G19: Gold | H19: Parle
H20: Voltas
H21: Fastrack
H22: Amul
H23: Realme
A25: 💡 To create named range: Select the list → click Name Box (left of formula bar) → type name (e.g., RegionList) → Enter. Then use =RegionList in Data Validation.

Sheet Chart_Data
A1: 📊 CHART DATA — Summarized Tables for Visualization
A2: TABLE 1: Sales by Region
A3: Region | B3: Total Sales (₹) | C3: Orders | D3: Avg Order (₹)
A4: North | B4: 1250000 | C4: 127 | D4: 9843
A5: South | B5: 1840000 | C5: 185 | D5: 9946
A6: East | B6: 860000 | C6: 86 | D6: 10000
A7: West | B7: 1520000 | C7: 152 | D7: 10000
A9: TABLE 2: Monthly Sales Trend
A10: Month | B10: Total Sales (₹) | C10: Orders | D10: Growth %
A11: Jan-2024 | B11: 420000 | C11: 42
A12: Feb-2024 | B12: 380000 | C12: 38 | D12: -9.5
A13: Mar-2024 | B13: 510000 | C13: 51 | D13: 34.2
A14: Apr-2024 | B14: 470000 | C14: 47 | D14: -7.8
A15: May-2024 | B15: 620000 | C15: 62 | D15: 31.9
A16: Jun-2024 | B16: 590000 | C16: 59 | D16: -4.8
A17: Jul-2024 | B17: 700000 | C17: 70 | D17: 18.6
A18: Aug-2024 | B18: 650000 | C18: 65 | D18: -7.1
A19: Sep-2024 | B19: 720000 | C19: 72 | D19: 10.8
A20: Oct-2024 | B20: 810000 | C20: 81 | D20: 12.5
A21: Nov-2024 | B21: 880000 | C21: 88 | D21: 8.6
A22: Dec-2024 | B22: 730000 | C22: 73 | D22: -17
A24: TABLE 3: Sales by Category
A25: Category | B25: Sales (₹) | C25: % Share | D25: Orders
A26: Electronics | B26: 2750000 | C26: 0.503 | D26: 275
A27: Fashion | B27: 1100000 | C27: 0.201 | D27: 165
A28: Home | B28: 820000 | C28: 0.15 | D28: 82
A29: Grocery | B29: 480000 | C29: 0.088 | D29: 120
A30: Jewellery | B30: 320000 | C30: 0.058 | D30: 32
A32: TABLE 4: Order Status Distribution
A33: Status | B33: Count | C33: % Share
A34: Delivered | B34: 365 | C34: 0.76
A35: Shipped | B35: 72 | C35: 0.15
A36: Returned | B36: 29 | C36: 0.06
A37: Cancelled | B37: 14 | C37: 0.03
A39: TABLE 5: Top 10 Products by Sales
A40: Product | B40: Sales (₹) | C40: Qty Sold | D40: Category
A41: iPhone 14 Pro | B41: 890000 | C41: 10 | D41: Electronics
A42: HP Pavilion Laptop | B42: 550000 | C42: 10 | D42: Electronics
A43: Whirlpool 1.5T AC | B43: 380000 | C43: 10 | D43: Home
A44: LG Refrigerator | B44: 420000 | C44: 10 | D44: Home
...

Sheet Visualization_Guide
A1: 📊 DATA VISUALIZATION GUIDE — Charts, When to Use & How to Build
A3: CHART SELECTION GUIDE
A4: Chart Type | B4: Best Used For | C4: Example Use Case | D4: Data Needed | E4: Avoid When
A5: Column Chart | B5: Compare values across categories | C5: Sales by Region (North vs South vs East vs West) | D5: Category | Value | E5: Too many categories (>10)
A6: Bar Chart (Horizontal) | B6: Ranking or long category names | C6: Top 10 Products by Sales | D6: Item Name | Value | E6: Showing time trends
A7: Line Chart | B7: Show trend over time | C7: Monthly Sales Trend Jan–Dec | D7: Time Period | Value | E7: Comparing unrelated categories
A8: Pie Chart | B8: Show proportion of a whole | C8: Category-wise Sales Share | D8: Category | % | E8: More than 6 slices — use Donut
A9: Donut Chart | B9: Same as pie but with center info | C9: Order Status Distribution | D9: Status | Count | E9: Too many small slices
A10: Clustered Column | B10: Compare multiple series | C10: Sales vs Target by Region | D10: Category | Series1 | Series2 | E10: Too many series (>3)
A11: Area Chart | B11: Cumulative trend | C11: Running Total of Sales | D11: Time | Cumulative Value | E11: Non-time series data
A12: Scatter Plot | B12: Correlation between 2 variables | C12: Price vs Quantity Sold | D12: X value | Y value | E12: Categorical data
A14: HOW TO BUILD EACH CHART — Step-by-Step
A15: CHART 1: Sales by Region (Column Chart)
A16: 1. Go to Chart_Data sheet → Select A4:B8 (Region + Total Sales)
A17: 2. Insert tab → Charts group → Insert Column Chart → Clustered Column
A18: 3. Click Chart Title → Type 'Total Sales by Region'
A19: 4. Right-click bars → Add Data Labels → Show Values
A20: 5. Chart Design tab → Change Colors → choose blue family
A21: 6. Format: Remove gridlines, add axis titles (Region / Sales in ₹)
A23: CHART 2: Monthly Sales Trend (Line Chart)
A24: 1. Select Chart_Data!A13:B25 (Month + Sales)
A25: 2. Insert → Charts → Line → Line with Markers
A26: 3. Right-click line → Add Trendline → Linear → check 'Display Equation'
... A48: ❌ COMMON CHART MISTAKES BEGINNERS MAKE
A49: ❌ MISTAKE | F49: ✅ CORRECT APPROACH
A50: Using 3D charts (3D Pie, 3D Column) | F50: Use 2D charts only — 3D distorts visual perception
A51: Pie chart with 7+ slices | F51: Group small slices into 'Other' — max 6 slices
A52: No chart title or axis labels | F52: Always add: Title + X-axis + Y-axis labels + Units
A53: Too many colors (rainbow charts) | F53: Use 1–3 colors max. Use color to highlight important data only
A54: Line chart for categories (non-time) | F54: Line = time series only. Use Bar/Column for categories
A55: Starting Y-axis at non-zero to exaggerate | F55: Keep Y-axis at 0 unless justified. Misleads viewers
A56: No data labels on pie chart | F56: Always show % labels on pie/donut charts
A57: Cluttered chart with too much data | F57: Simplify — one chart = one message

Sheet Dashboard
A1: 🛒 E-COMMERCE SALES PERFORMANCE DASHBOARD — FY 2024 | India Region
A2: Data Source: Flipkart-style E-Commerce Dataset | 480 Clean Records | January – June 2024 | Last Updated: April 2025
A4: 💰 Total Sales | D4: 📦 Total Orders | G4: 📈 Avg Order Value | J4: ✅ Delivered % | M4: 🔄 Return Rate
A5: ₹54,70,000 | D5: 480 | G5: ₹11,396 | J5: 76.0% | M5: 6.0%
A6: +12.3% vs LY | D6: ↑ 8.2% MoM | G6: Target: ₹10,000 | J6: Target: 80% | M6: Below 7% = Good
A9: 📊 SALES BY REGION | H9: 📈 MONTHLY SALES TREND
A10: Region | B10: Sales (₹) | C10: Orders | D10: Avg Order | E10: % Share | F10: Status | H10: Month | I10: Sales | J10: Orders | K10: Growth | L10: Target Hit?
A11: North | B11: ₹12,50,000 | C11: 127 | D11: ₹9,843 | E11: 22.8% | F11: ⬆ Good | H11: Jan | I11: ₹4,20,000 | J11: 42 | K11: - | L11: ✅
A12: South | B12: ₹18,40,000 | C12: 185 | D12: ₹9,946 | E12: 33.6% | F12: ⬆ Best | H12: Feb | I12: ₹3,80,000 | J12: 38 | K12: -9.5% | L12: ❌
A13: East | B13: ₹8,60,000 | C13: 86 | D13: ₹10,000 | E13: 15.7% | F13: → Average | H13: Mar | I13: ₹5,10,000 | J13: 51 | K13: +34.2% | L13: ✅
A14: West | B14: ₹15,20,000 | C14: 152 | D14: ₹10,000 | E14: 27.8% | F14: ⬆ Good | H14: Apr | I14: ₹4,70,000 | J14: 47 | K14: -7.8% | L14: ✅
H15: May | I15: ₹6,20,000 | J15: 62 | K15: +31.9% | L15: ✅
H16: Jun | I16: ₹5,90,000 | J16: 59 | K16: -4.8% | L16: ✅
A17: 🥧 CATEGORY PERFORMANCE | H17: 🏆 TOP 5 PRODUCTS
A18: Category | B18: Sales (₹) | C18: Share | D18: Orders | E18: Avg (₹) | F18: Rank | H18: Product | I18: Category | J18: Sales | K18: Orders | L18: Rank
A19: Electronics | B19: ₹27,50,000 | C19: 50.3% | D19: 275 | E19: ₹10,000 | F19: 1 | H19: iPhone 14 Pro | I19: Electronics | J19: ₹8,90,000 | K19: 10 | L19: 1
A20: Fashion | B20: ₹11,00,000 | C20: 20.1% | D20: 165 | E20: ₹6,667 | F20: 2 | H20: HP Laptop | I20: Electronics | J20: ₹5,50,000 | K20: 10 | L20: 2
A21: Home | B21: ₹8,20,000 | C21: 15.0% | D21: 82 | E21: ₹10,000 | F21: 3 | H21: LG Refrigerator | I21: Home | J21: ₹4,20,000 | K21: 10 | L21: 3
A22: Grocery | B22: ₹4,80,000 | C22: 8.8% | D22: 120 | E22: ₹4,000 | F22: 4 | H22: Whirlpool AC | I22: Home | J22: ₹3,80,000 | K22: 10 | L22: 4
A23: Jewellery | B23: ₹3,20,000 | C23: 5.8% | D23: 32 | E23: ₹10,000 | F23: 5 | H23: Samsung TV | I23: Electronics | J23: ₹3,50,000 | K23: 10 | L23: 5
A25: 📌 NEXT STEPS: 1) Create Pivot Tables from Clean_Data sheet 2) Insert PivotCharts 3) Add Slicers for Region, Category, Order_Status 4) Add Timeline for Order_Date 5) Connect all slicers via Report Connections

Sheet Assignment
A1: 🎯 MINI PROJECT ASSIGNMENT — Student Performance Data Cleaning & Dashboard
A2: Telugu: Ee assignment complete chesi screenshot comment lo share cheyyandi. Best submissions featured avutaayi!
A3: TASKS (Total: 100 Marks)
A4: # | B4: Task | C4: Details | D4: Marks | E4: Your Answer
A5: 1 | B5: TRIM + PROPER on Student Names | C5: Remove spaces, fix casing | D5: 10
A6: 2 | B6: Remove Duplicate Student_IDs | C6: Use COUNTIF + Remove Duplicates | D6: 10
A7: 3 | B7: Handle Blank Names | C7: Fill with 'Unknown Student' | D7: 10
A8: 4 | B8: Fix Invalid CGPA (>10 or <0) | C8: Flag as 'Check Required' | D8: 10
A9: 5 | B9: Standardize Gender (M→Male, F→Female) | C9: Use IF/SWITCH formula | D9: 10
A10: 6 | B10: Data Validation on Placement_Status | C10: Dropdown: Placed/Not Placed | D10: 10
A11: 7 | B11: Chart: Avg CGPA by Branch | C11: Clustered Column Chart | D11: 15
A12: 8 | B12: Chart: Placement Rate by College | C12: Pie/Donut Chart | D12: 15
A13: 9 | B13: Build a Mini KPI Dashboard | C13: 3 KPI cards + 2 charts | D13: 10
A14: TOTAL: 100 Marks | Submission: Screenshot in YouTube comments | Deadline: 7 days from video upload
A16: ASSIGNMENT DATASET — Student Performance Data (With Issues)
A17: Student_ID | B17: Name | C17: College | D17: City | E17: Branch | F17: Semester | G17: CGPA | H17: Attendance_% | I17: Backlogs | J17: Placement_Status | K17: Package_LPA | L17: Gender | M17: Year_of_Passing
A18: STU-1001 | B18: anita verma | C18: Andhra University | D18: Kolkata | E18: EEE | F18: 3 | G18: 8.31 | H18: 99 | I18: 2 | J18: Placed | K18: 8.9 | L18: female | M18: 2024
A19: STU-1002 | B19: SNEHA REDDY | C19: IIT Hyderabad | D19: Bengaluru | E19: EEE | F19: 4 | G19: 8.48 | H19: 68 | I19: 5 | J19: Not Placed | K19: 13.6 | L19: Female | M19: 2023
A20: STU-1003 | B20: meera n | C20: BITS Pilani | D20: Kolkata | E20: Chemical | F20: 1 | G20: 5.33 | H20: 98.7 | I20: 2 | J20: placed | K20: 14.1 | L20: F | M20: 2024
A21: STU-1004 | B21: kabir mehta | C21: Osmania | D21: Bengaluru | E21: IT | F21: 7 | G21: 5.14 | H21: 85.8 | I21: 4 | J21: Not Placed | K21: 4.7 | L21: female | M21: 2023
A22: STU-1005 | B22: priya devi | C22: VIT | D22: Delhi | E22: EEE | F22: 1 | G22: 10.15 | H22: 75.1 | I22: 0 | J22: Placed | L22: FEMALE | M22: 2025
A23: STU-1005 | B23: Divya Nair | C23: IIT Hyderabad | D23: Bengaluru | E23: ECE | F23: 6 | G23: 5.78 | H23: 95.7 | I23: 4 | J23: Placed | L23: MALE | M23: 2023
A24: STU-1007 | B24: kavya rao | C24: JNTU | D24: Delhi | E24: ECE | F24: 2 | G24: 9.16 | H24: 52.2 | I24: 4 | J24: Not Placed | K24: 18.9 | L24: F | M24: 2023
A25: STU-1008 | B25: Divya Nair | C25: VIT | D25: Bengaluru | E25: IT | F25: 7 | G25: 10.35 | H25: 68.6 | I25: 5 | J25: Not Placed | K25: 19.5 | L25: Other | M25: 2023
A26: STU-1009 | B26: SNEHA REDDY | C26: VIT | D26: Hyderabad | E26: CSE | F26: 4 | G26: 7.47 | H26: 56.3 | I26: 3 | J26: Placed | K26: 8.7 | L26: Male | M26: 2024
A27: STU-1010 | B27: SNEHA REDDY | C27: BITS Pilani | D27: Pune | E27: Mechanical | F27: 1 | G27: 10.22 | H27: 102.5 | I27: 4 | J27: placed | L27: female | M27: 2023
A28: STU-1011 | C28: Osmania | D28: Chennai | E28: Mechanical | F28: 1 | G28: 8.93 | H28: 72.8 | I28: 2 | J28: not placed | L28: Female | M28: 2023
A29: STU-1012 | B29: AMIT SHAH | C29: BITS Pilani | D29: Chennai | E29: EEE | F29: 5 | G29: 9.94 | H29: 59 | I29: 4 | J29: placed | L29: Other | M29: 2025
A30: STU-1013 | B30: Arjun Singh | C30: NIT Warangal | D30: Hyderabad | E30: IT | F30: 5 | G30: 9.59 | H30: 91.5 | I30: 3 | J30: Placed | L30: female | M30: 2025
A31: STU-1014 | B31: SNEHA REDDY | C31: VIT | D31: Pune | E31: IT | F31: 5 | G31: 6.02 | H31: 52.3 | I31: 5 | J31: not placed | K31: 19.3 | L31: F | M31: 2023
A32: STU-1015 | B32: Divya Nair | C32: Osmania | D32: Chennai | E32: CSE | F32: 5 | G32: 7.55 | H32: 85.6 | I32: 0 | J32: Not Placed | L32: M | M32: 2023
A33: STU-1016 | B33: SNEHA REDDY | C33: NIT Warangal | D33: Bengaluru | E33: Civil | F33: 5 | G33: 7.75 | H33: 89.6 | I33: 5 | J33: Not Placed | K33: 13.1 | L33: Female | M33: 2023
A34: STU-1017 | B34: RAVI KUMAR | C34: NIT Warangal | D34: Pune | E34: Civil | F34: 3 | G34: 9.69 | H34: 84.1 | I34: 0 | J34: Placed | K34: 23.8 | L34: FEMALE | M34: 2024
A35: STU-1018 | C35: Andhra University | D35: Hyderabad | E35: CSE | F35: 5 | G35: 6.05 | H35: 73.3 | I35: 1 | J35: placed | K35: 4.7 | L35: female | M35: 2024
A36: STU-1019 | B36: priya devi | C36: JNTU | D36: Hyderabad | E36: CSE | F36: 4 | G36: 10.06 | H36: 90.9 | I36: 3 | J36: PLACED | K36: 3.7 | L36: Other | M36: 2023
A37: STU-1020 | B37: kabir mehta | C37: NIT Warangal | D37: Pune | E37: Mechanical | F37: 1 | G37: 5.12 | H37: 81 | I37: 0 | J37: NOT PLACED | L37: male | M37: 2025
A38: STU-1021 | B38: ROHIT YADAV | C38: BITS Pilani | D38: Mumbai | E38: IT | F38: 8 | G38: 5.96 | H38: 50.7 | I38: 1 | J38: placed | K38: 17.4 | L38: Male | M38: 2023
A39: STU-1022 | B39: SNEHA REDDY | C39: Andhra University | D39: Kolkata | E39: Mechanical | F39: 8 | G39: 6.29 | H39: 74.6 | I39: 1 | J39: not placed | L39: Male | M39: 2023
A40: STU-1023 | B40: Divya Nair | C40: BITS Pilani | D40: Chennai | E40: Civil | F40: 3 | G40: 5.49 | H40: 70.2 | I40: 2 | J40: not placed | K40: 15 | L40: FEMALE | M40: 2025
A41: STU-1024 | B41: Arjun Singh | C41: NIT Warangal | D41: Pune | E41: Civil | F41: 7 | G41: 8.19 | H41: 70.5 | I41: 2 | J41: NOT PLACED | K41: 19.9 | L41: Female | M41: 2023
...
